Workbook

Sheet Nilesh Send Tannage 
B1: Day April-26 | D1: 1 | E1: 2 | F1: 3 | G1: 4 | H1: 5 | I1: 6 | J1: 7 | K1: 8 | L1: 9 | M1: 10 | N1: 11 | O1: 12 | P1: 13 | Q1: 14 | R1: 15 | S1: 16 | T1: 17 | U1: 18 | V1: 19 | W1: 20 | X1: 21 | Y1: 22 | Z1: 23 | AA1: 24 | AB1: 25 | AC1: 26 | AD1: 27 | AE1: 28 | AF1: 29 | AG1: 30 | AH1: Total
B2: FINAL TEAM 1 | D2: 1 | E2: 2 | F2: 3 | G2: 4 | H2: 5 | I2: 6 | J2: 7 | K2: 8 | L2: 9 | M2: 10 | N2: 11 | O2: 12 | P2: 13 | Q2: 14 | R2: 15 | S2: 16 | T2: 17 | U2: 18 | V2: 19 | W2: 20 | X2: 21 | Y2: 22 | Z2: 23 | AA2: 24 | AB2: 25 | AC2: 26 | AD2: 27 | AE2: 28 | AF2: 29 | AG2: 30 | AH2: Total
B3: TOTAL AMOUNT | D3: =D5*D4 -> 0 | E3: =E5*E4 -> 4704.92 | F3: =F5*F4 -> 5196.62 | G3: =G5*G4 -> 5555.22 | H3: =H5*H4 -> 5927.68 | I3: =I5*I4 -> 4180.22 | J3: =J5*J4 -> 5725.28 | K3: =K5*K4 -> 0 | ... AG3: =AG5*AG4 -> 5278.46 | AH3: =SUM(D3:AG3) -> 128661.06
B4: TOTAL MT | E4: 21.386 | F4: 23.621 | G4: 25.251 | H4: 26.944 | I4: 19.001 | J4: 26.024 | L4: 18.952 | M4: 31.11 | N4: 25.191 | O4: 20.545 | P4: 20.893 | Q4: 17.717 | S4: 16.626 | T4: 23.22 | U4: 23.632 | V4: 26.822 | W4: 21.413 | X4: 32.106 | Z4: 21.284 | AA4: 19.088 | AB4: 20.859 | AC4: 19.013 | AD4: 21.611 | AE4: 18.679 | AF4: 19.842 | AG4: 23.993 | AH4: =SUM(D4:AG4) -> 584.823
B5: Rate | D5: 220 | E5: 220 | F5: 220 | G5: 220 | H5: 220 | I5: 220 | J5: 220 | K5: 220 | L5: 220 | M5: 220 | N5: 220 | O5: 220 | P5: 220 | Q5: 220 | R5: 220 | S5: 220 | T5: 220 | U5: 220 | V5: 220 | W5: 220 | X5: 220 | Y5: 220 | Z5: 220 | AA5: 220 | AB5: 220 | AC5: 220 | AD5: 220 | AE5: 220 | AF5: 220 | AG5: 220
B6: No.of Manpawar | E6: 5 | F6: 6 | G6: 6 | H6: 6 | I6: 6 | J6: 6 | L6: 5 | M6: 6 | N6: 6 | O6: 6 | P6: 5 | Q6: 5 | S6: 6 | T6: 6 | U6: 6 | V6: 6 | W6: 6 | X6: 5 | Z6: 5 | AA6: 5 | AB6: 5 | AC6: 5 | AD6: 5 | AE6: 5 | AF6: 5 | AG6: 6 | AH6: =SUM(D6:AG6) -> 144
B7: Paid Amount | D7: =D3/D6 -> #DIV/0! | E7: =E3/E6 -> 940.984 | F7: =F3/F6 -> 866.10333 | G7: =G3/G6 -> 925.87 | H7: =H3/H6 -> 987.94667 | I7: =I3/I6 -> 696.70333 | J7: =J3/J6 -> 954.21333 | K7: =K3/K6 -> #DIV/0! | ... AG7: =AG3/AG6 -> 879.74333 | AH7: =SUM(D7:AG7) -> #DIV/0!
A8: 1 | B8: Mr. ANIL G MALI | C8: 101475240602 | E8: 940 | F8: 1130 | G8: 925 | H8: 987 | I8: 836 | J8: 954 | N8: 923 | P8: 919 | Q8: 779 | S8: 609 | T8: 851 | U8: 888 | V8: 983 | W8: 510 | X8: 1941 | AB8: 917 | AC8: 836 | AD8: 950 | AE8: 889 | AF8: 873 | AG8: 879 | AH8: =SUM(D8:AG8) -> 19519
A9: 2 | B9: Mr. REVANASIDDH SHIVAPPA ISHWARKATTI | C9: 101492178974 | D9: 550 | E9: 940 | F9: 1130 | G9: 925 | H9: 987 | I9: 836 | J9: 954 | K9: 550 | L9: 833 | M9: 1140 | N9: 923 | O9: 903 | P9: 919 | Q9: 779 | R9: 550 | S9: 609 | T9: 851 | U9: 888 | V9: 983 | W9: 1050 | X9: 1941 | Y9: 550 | Z9: 936 | AF9: 873 | AG9: 879 | AH9: =SUM(D9:AG9) -> 22479
A10: 3 | B10: Mr. JITENDRA SIDRAM KOLI | C10: 101603294918 | E10: 940 | F10: 1130 | G10: 925 | H10: 987 | I10: 836 | J10: 954 | L10: 833 | M10: 1140 | N10: 923 | O10: 903 | P10: 919 | S10: 609 | T10: 851 | U10: 888 | V10: 983 | W10: 1050 | X10: 690 | Z10: 936 | AA10: 839 | AB10: 917 | AC10: 836 | AE10: 889 | AF10: 873 | AG10: 879 | AH10: =SUM(D10:AG10) -> 21730
A11: 4 | B11: Mr. VIJAY BHARLE | C11: 101944505682 | F11: 176 | G11: 925 | H11: 987 | J11: 954 | L11: 833 | M11: 1140 | N11: 923 | O11: 903 | Q11: 779 | S11: 609 | T11: 851 | U11: 888 | V11: 983 | W11: 1050 | Z11: 936 | AA11: 839 | AB11: 917 | AC11: 836 | AD11: 950 | AG11: 879 | AH11: =SUM(D11:AG11) -> 17358
A12: 6 | B12: Mr. DIPAK DATTATRAY KUMBHAR | C12: 102052667942 | E12: 940 | G12: 925 | H12: 987 | I12: 836 | J12: 954 | K12: 550 | L12: 833 | M12: 1140 | N12: 923 | O12: 903 | P12: 919 | Q12: 779 | S12: 609 | T12: 851 | U12: 756 | V12: 983 | Z12: 936 | AA12: 839 | AB12: 917 | AC12: 836 | AD12: 950 | AE12: 889 | AG12: 879 | AH12: =SUM(D12:AG12) -> 20134
A13: 7 | B13: Mr. GIRISH SIDDHARAM MADYAL | C13: 101826609019 | E13: 940 | F13: 1130 | G13: 925 | H13: 987 | I13: 836 | J13: 954 | M13: 1140 | N13: 923 | O13: 903 | P13: 919 | Q13: 779 | S13: 609 | T13: 851 | U13: 888 | V13: 983 | W13: 1050 | X13: 1941 | Z13: 936 | AA13: 839 | AB13: 917 | AC13: 836 | AD13: 950 | AE13: 889 | AF13: 873 | AG13: 879 | AH13: =SUM(D13:AG13) -> 23877
B14: Mr. BHIMAHSNKAR SHARNAPPA ISHWARKATTI | C14: 102004077854 | AF14: 873 | AH14: =SUM(D14:AG14) -> 873
B15: Mr.SHVSNAND LANDAGE | L15: 833 | AH15: =SUM(D15:AG15) -> 833
B16: HARUN MULLA | X16: 550 | AH16: =SUM(D16:AG16) -> 550
B17: Fulari | AE17: 550 | AH17: =SUM(D17:AG17) -> 550
A18: 7 | B18: Pundalik Jadhav | M18: 1140 | AA18: 839 | AD18: 950 | AH18: =SUM(D18:AG18) -> 2929
B19: Total | D19: =SUM(D8:D18) -> 550 | E19: =SUM(E8:E18) -> 4700 | F19: =SUM(F8:F18) -> 4696 | G19: =SUM(G8:G18) -> 5550 | H19: =SUM(H8:H18) -> 5922 | I19: =SUM(I8:I18) -> 4180 | J19: =SUM(J8:J18) -> 5724 | K19: =SUM(K8:K18) -> 1100 | ... AH19: =SUM(AH8:AH18) -> 130832
B20: FINAL TEAM 2 | D20: =D19-D3 -> 550 | E20: =E19-E3 -> -4.92 | F20: =F19-F3 -> -500.62 | G20: =G19-G3 -> -5.22 | H20: =H19-H3 -> -5.68 | I20: =I19-I3 -> -0.22 | J20: =J19-J3 -> -1.28 | K20: =K19-K3 -> 1100 | ... AG20: =AG19-AG3 -> -4.46 | AH20: =SUM(D20:AG20) -> 2170.94
B21: TOTAL AMOUNT | D21: =D23*D22 -> 0 | E21: =E23*E22 -> 4045.14 | F21: =F23*F22 -> 3550.8 | G21: =G23*G22 -> 5346.66 | H21: =H23*H22 -> 3077.14 | I21: =I23*I22 -> 6698.34 | J21: =J23*J22 -> 4063.62 | K21: =K23*K22 -> 0 | ... AG21: =AG23*AG22 -> 5463.04 | AH21: =SUM(D21:AG21) -> 120609.94
B22: TOTAL MT | E22: 18.387 | F22: 16.14 | G22: 24.303 | H22: 13.987 | I22: 30.447 | J22: 18.471 | L22: 31.806 | M22: 23.796 | N22: 29.054 | O22: 20.71 | P22: 22.712 | Q22: 19.659 | S22: 22.044 | T22: 20.173 | U22: 24.774 | V22: 16.631 | X22: 30.148 | Z22: 20.175 | AA22: 23.181 | AB22: 22.116 | AC22: 17.191 | AD22: 20.657 | AE22: 22.811 | AF22: 14.022 | AG22: 24.832 | AH22: =SUM(D22:AG22) -> 548.227
B23: Rate | D23: 220 | E23: 220 | F23: 220 | G23: 220 | H23: 220 | I23: 220 | J23: 220 | K23: 220 | L23: 220 | M23: 220 | N23: 220 | O23: 220 | P23: 220 | Q23: 220 | R23: 220 | S23: 220 | T23: 220 | U23: 220 | V23: 220 | W23: 220 | X23: 220 | Y23: 220 | Z23: 220 | AA23: 220 | AB23: 220 | AC23: 220 | AD23: 220 | AE23: 220 | AF23: 220 | AG23: 220
B24: No.of Manpawar | E24: 5 | F24: 6 | G24: 6 | H24: 6 | I24: 5 | J24: 4 | L24: 6 | M24: 5 | N24: 6 | O24: 6 | P24: 6 | Q24: 6 | S24: 6 | T24: 6 | U24: 6 | V24: 5 | X24: 5 | Z24: 6 | AA24: 5 | AB24: 5 | AC24: 5 | AD24: 5 | AE24: 5 | AF24: 5 | AG24: 5 | AH24: =SUM(D24:AG24) -> 136
B25: Paid Amount | D25: =D21/D24 -> #DIV/0! | E25: =E21/E24 -> 809.028 | F25: =F21/F24 -> 591.8 | G25: =G21/G24 -> 891.11 | H25: =H21/H24 -> 512.85667 | I25: =I21/I24 -> 1339.668 | J25: =J21/J24 -> 1015.905 | K25: =K21/K24 -> #DIV/0! | ... AG25: =AG21/AG24 -> 1092.608 | AH25: =SUM(D25:AG25) -> #DIV/0!
A26: 1 | B26: Ambare D.K | F26: 591 | G26: 891 | H26: 280 | L26: 982 | N26: 1065 | O26: 865 | P26: 686 | Q26: 610 | S26: 551 | T26: 740 | U26: 908 | V26: 732 | W26: 550 | X26: 1326 | Z26: 739 | AB26: 973 | AH26: =SUM(D26:AG26) -> 12489
A27: 2 | B27: Mr. KASHINATH JAGANATH BIRJADAR | C27: 101818174092 | E27: 809 | F27: 591 | G27: 891 | H27: 559 | I27: 1339 | J27: 1015 | L27: 1202 | M27: 1047 | N27: 1065 | O27: 865 | P27: 862 | Q27: 742 | S27: 859 | T27: 740 | U27: 908 | W27: 550 | X27: 1326 | Z27: 739 | AA27: 1019 | AC27: 756 | AD27: 908 | AE27: 1003 | AF27: 616 | AG27: 1004 | AH27: =SUM(D27:AG27) -> 21415
A28: 3 | B28: Mr. BHIMAHSNKAR SHARNAPPA ISHWARKATTI | C28: 102004077854 | E28: 809 | F28: 591 | G28: 891 | H28: 559 | I28: 1339 | J28: 1015 | L28: 1202 | M28: 1047 | N28: 1065 | O28: 865 | P28: 862 | Q28: 742 | S28: 859 | T28: 740 | U28: 908 | V28: 732 | W28: 550 | X28: 1326 | Z28: 739 | AA28: 1019 | AB28: 973 | AC28: 756 | AD28: 908 | AE28: 1003 | AF28: 616 | AG28: 1114 | AH28: =SUM(D28:AG28) -> 23230
A29: 4 | B29: Mr. SHIVANAND KANTAPPA KOSHTI | C29: 101817173110 | E29: 809 | F29: 591 | G29: 891 | H29: 559 | I29: 1339 | L29: 1202 | M29: 1047 | N29: 1065 | O29: 230 | P29: 862 | Q29: 742 | S29: 859 | T29: 740 | U29: 908 | V29: 732 | X29: 1326 | Z29: 739 | AA29: 1019 | AB29: 973 | AC29: 756 | AD29: 908 | AE29: 1003 | AF29: 616 | AG29: 1114 | AH29: =SUM(D29:AG29) -> 21030
A30: 5 | B30: Mr. KHAJASAHEB GULAB HIMONE | C30: 102120964651 | E30: 809 | F30: 591 | G30: 891 | H30: 559 | I30: 1339 | J30: 1015 | L30: 1202 | M30: 1047 | N30: 1065 | O30: 865 | P30: 862 | Q30: 742 | S30: 859 | T30: 740 | U30: 908 | V30: 732 | W30: 550 | X30: 1326 | Z30: 739 | AA30: 1019 | AB30: 973 | AC30: 756 | AD30: 908 | AE30: 1003 | AF30: 616 | AG30: 1114 | AH30: =SUM(D30:AG30) -> 23230
A31: 6 | B31: Mr. VISHAL SURESH MANE | C31: 101432431093 | E31: 809 | F31: 591 | G31: 891 | H31: 559 | I31: 1339 | J31: 1015 | L31: 1202 | M31: 1047 | N31: 1065 | O31: 865 | P31: 862 | Q31: 742 | S31: 859 | T31: 740 | U31: 908 | V31: 732 | Z31: 739 | AA31: 1019 | AB31: 973 | AC31: 756 | AD31: 908 | AE31: 1003 | AF31: 616 | AG31: 1114 | AH31: =SUM(D31:AG31) -> 21354
B32: Total | D32: =SUM(D26:D31) -> 0 | E32: =SUM(E26:E31) -> 4045 | F32: =SUM(F26:F31) -> 3546 | G32: =SUM(G26:G31) -> 5346 | H32: =SUM(H26:H31) -> 3075 | I32: =SUM(I26:I31) -> 6695 | J32: =SUM(J26:J31) -> 4060 | K32: =SUM(K26:K31) -> 0 | ... AH32: =SUM(AH26:AH31) -> 122748
B33: HAND EMARY 1 (GroupA) | D33: =D32-D21 -> 0 | E33: =E32-E21 -> -0.14 | F33: =F32-F21 -> -4.8 | G33: =G32-G21 -> -0.66 | H33: =H32-H21 -> -2.14 | I33: =I32-I21 -> -3.34 | J33: =J32-J21 -> -3.62 | K33: =K32-K21 -> 0 | ... AG33: =AG32-AG21 -> -3.04 | AH33: =SUM(D33:AG33) -> 2138.06
B34: TOTAL AMOUNT | D34: =D35*D36 -> 0 | E34: =E35*E36 -> 6940.8 | F34: =F35*F36 -> 8104.96 | G34: =G35*G36 -> 7467.008 | H34: =H35*H36 -> 8408.32 | I34: =I35*I36 -> 6601.92 | J34: =J35*J36 -> 5987.2 | K34: =K35*K36 -> 0 | ... AG34: =AG35*AG36 -> 6517.76 | AH34: =SUM(D34:AG34) -> 168183.49
B35: TOTAL MT | E35: 21.69 | F35: 25.328 | G35: 23.3344 | H35: 26.276 | I35: 20.631 | J35: 18.71 | L35: 20.54 | M35: 24.714 | N35: 17.58 | O35: 19.414 | P35: 14.583 | Q35: 14.877 | R35: 17.008 | S35: 13.17 | T35: 16.932 | U35: 19.653 | V35: 17.759 | W35: 21.011 | X35: 21.7 | Y35: 11.374 | Z35: 12.294 | AA35: 14.706 | AB35: 16.89 | AC35: 20.04 | AD35: 20.792 | AE35: 17.54 | AF35: 16.659 | AG35: 20.368 | AH35: =SUM(D35:AG35) -> 525.5734
B36: Rate | D36: 320 | E36: 320 | F36: 320 | G36: 320 | H36: 320 | I36: 320 | J36: 320 | K36: 320 | L36: 320 | M36: 320 | N36: 320 | O36: 320 | P36: 320 | Q36: 320 | R36: 320 | S36: 320 | T36: 320 | U36: 320 | V36: 320 | W36: 320 | X36: 320 | Y36: 320 | Z36: 320 | AA36: 320 | AB36: 320 | AC36: 320 | AD36: 320 | AE36: 320 | AF36: 320 | AG36: 320
B37: No.of Manpawar | E37: 7 | F37: 7 | G37: 7 | H37: 8 | I37: 7 | J37: 7 | L37: 7 | M37: 7 | N37: 6 | O37: 6 | P37: 7 | Q37: 7 | R37: 7 | S37: 5 | T37: 7 | U37: 7 | V37: 6 | W37: 8 | X37: 8 | Y37: 6 | Z37: 6 | AA37: 7 | AB37: 7 | AC37: 8 | AD37: 8 | AE37: 7 | AF37: 7 | AG37: 8 | AH37: =SUM(D37:AG37) -> 195
B38: Paid Amount | D38: =D34/D37 -> #DIV/0! | E38: =E34/E37 -> 991.54286 | F38: =F34/F37 -> 1157.8514 | G38: =G34/G37 -> 1066.7154 | H38: =H34/H37 -> 1051.04 | I38: =I34/I37 -> 943.13143 | J38: =J34/J37 -> 855.31429 | K38: =K34/K37 -> #DIV/0! | ... AG38: =AG34/AG37 -> 814.72 | AH38: =SUM(D38:AG38) -> #DIV/0!
A39: 1 | B39: Mr. NAMDEV DURGAPPA BANDGAR | C39: 101407413648 | H39: 1131 | I39: 1008 | J39: 906 | L39: 1003 | M39: 1226 | N39: 1025 | O39: 1132 | P39: 686 | Q39: 701 | R39: 815 | T39: 811 | U39: 956 | V39: 1026 | W39: 900 | X39: 1065 | Y39: 617 | Z39: 708 | AA39: 721 | AB39: 809 | AC39: 837 | AG39: 902 | AH39: =SUM(D39:AG39) -> 18985
A40: 2 | B40: Mr. KHALID ILAI SHAIKH | C40: 101373078654 | E40: 1108 | F40: 1259 | G40: 1265 | H40: 1131 | I40: 1008 | J40: 906 | L40: 1003 | M40: 1226 | N40: 1025 | O40: 1132 | P40: 686 | Q40: 701 | S40: 1038 | T40: 811 | U40: 956 | W40: 900 | X40: 1065 | Z40: 708 | AA40: 721 | AB40: 809 | AC40: 837 | AG40: 902 | AH40: =SUM(D40:AG40) -> 21197
...

Sheet nilesh sir tannage
B1: Day April-26 | D1: 1 | E1: 2 | F1: 3 | G1: 4 | H1: 5 | I1: 6 | J1: 7 | K1: 8 | L1: 9 | M1: 10 | N1: 11 | O1: 12 | P1: 13 | Q1: 14 | R1: 15 | S1: 16 | T1: 17 | U1: 18 | V1: 19 | W1: 20 | X1: 21 | Y1: 22 | Z1: 23 | AA1: 24 | AB1: 25 | AC1: 26 | AD1: 27 | AE1: 28 | AF1: 29 | AG1: 30 | AH1: Total
B2: FINAL TEAM 1 | D2: 1 | E2: 2 | F2: 3 | G2: 4 | H2: 5 | I2: 6 | J2: 7 | K2: 8 | L2: 9 | M2: 10 | N2: 11 | O2: 12 | P2: 13 | Q2: 14 | R2: 15 | S2: 16 | T2: 17 | U2: 18 | V2: 19 | W2: 20 | X2: 21 | Y2: 22 | Z2: 23 | AA2: 24 | AB2: 25 | AC2: 26 | AD2: 27 | AE2: 28 | AF2: 29 | AG2: 30 | AH2: Total
B3: TOTAL AMOUNT | D3: =D5*D4 -> 0 | E3: =E5*E4 -> 4704.92 | F3: =F5*F4 -> 5196.62 | G3: =G5*G4 -> 5555.22 | H3: =H5*H4 -> 5927.68 | I3: =I5*I4 -> 4180.22 | J3: =J5*J4 -> 5725.28 | K3: =K5*K4 -> 0 | ... AG3: =AG5*AG4 -> 5278.46 | AH3: =SUM(D3:AG3) -> 128661.06
B4: TOTAL MT | E4: 21.386 | F4: 23.621 | G4: 25.251 | H4: 26.944 | I4: 19.001 | J4: 26.024 | L4: 18.952 | M4: 31.11 | N4: 25.191 | O4: 20.545 | P4: 20.893 | Q4: 17.717 | S4: 16.626 | T4: 23.22 | U4: 23.632 | V4: 26.822 | W4: 21.413 | X4: 32.106 | Z4: 21.284 | AA4: 19.088 | AB4: 20.859 | AC4: 19.013 | AD4: 21.611 | AE4: 18.679 | AF4: 19.842 | AG4: 23.993 | AH4: =SUM(D4:AG4) -> 584.823
B5: Rate | D5: 220 | E5: 220 | F5: 220 | G5: 220 | H5: 220 | I5: 220 | J5: 220 | K5: 220 | L5: 220 | M5: 220 | N5: 220 | O5: 220 | P5: 220 | Q5: 220 | R5: 220 | S5: 220 | T5: 220 | U5: 220 | V5: 220 | W5: 220 | X5: 220 | Y5: 220 | Z5: 220 | AA5: 220 | AB5: 220 | AC5: 220 | AD5: 220 | AE5: 220 | AF5: 220 | AG5: 220
B6: No.of Manpawar | E6: 5 | F6: 6 | G6: 6 | H6: 6 | I6: 6 | J6: 6 | L6: 5 | M6: 6 | N6: 6 | O6: 6 | P6: 5 | Q6: 5 | S6: 6 | T6: 6 | U6: 6 | V6: 6 | W6: 6 | X6: 5 | Z6: 5 | AA6: 5 | AB6: 5 | AC6: 5 | AD6: 5 | AE6: 5 | AF6: 5 | AG6: 6 | AH6: =SUM(D6:AG6) -> 144
B7: Paid Amount | D7: =D3/D6 -> #DIV/0! | E7: =E3/E6 -> 940.984 | F7: =F3/F6 -> 866.10333 | G7: =G3/G6 -> 925.87 | H7: =H3/H6 -> 987.94667 | I7: =I3/I6 -> 696.70333 | J7: =J3/J6 -> 954.21333 | K7: =K3/K6 -> #DIV/0! | ... AG7: =AG3/AG6 -> 879.74333 | AH7: =SUM(D7:AG7) -> #DIV/0!
A8: 1 | B8: Mr. ANIL G MALI | C8: 101475240602 | E8: 940 | F8: 1130 | G8: 925 | H8: 987 | I8: 836 | J8: 954 | N8: 923 | P8: 919 | Q8: 779 | S8: 609 | T8: 851 | U8: 888 | V8: 983 | W8: 510 | X8: 1941 | AB8: 917 | AC8: 836 | AD8: 950 | AE8: 889 | AF8: 873 | AG8: 879 | AH8: =SUM(D8:AG8) -> 19519 | AI8: =COUNT(D8:AG8) -> 21
A9: 2 | B9: Mr. REVANASIDDH SHIVAPPA ISHWARKATTI | C9: 101492178974 | D9: 550 | E9: 940 | F9: 1130 | G9: 925 | H9: 987 | I9: 836 | J9: 954 | K9: 550 | L9: 833 | M9: 1140 | N9: 923 | O9: 903 | P9: 919 | Q9: 779 | R9: 550 | S9: 609 | T9: 851 | U9: 888 | V9: 983 | W9: 1050 | X9: 1941 | Y9: 550 | Z9: 936 | AF9: 873 | AG9: 879 | AH9: =SUM(D9:AG9) -> 22479 | AI9: =COUNT(D9:AG9) -> 25
A10: 3 | B10: Mr. JITENDRA SIDRAM KOLI | C10: 101603294918 | E10: 940 | F10: 1130 | G10: 925 | H10: 987 | I10: 836 | J10: 954 | L10: 833 | M10: 1140 | N10: 923 | O10: 903 | P10: 919 | S10: 609 | T10: 851 | U10: 888 | V10: 983 | W10: 1050 | X10: 690 | Z10: 936 | AA10: 839 | AB10: 917 | AC10: 836 | AE10: 889 | AF10: 873 | AG10: 879 | AH10: =SUM(D10:AG10) -> 21730 | AI10: =COUNT(D10:AG10) -> 24
A11: 4 | B11: Mr. VIJAY BHARLE | C11: 101944505682 | F11: 176 | G11: 925 | H11: 987 | J11: 954 | L11: 833 | M11: 1140 | N11: 923 | O11: 903 | Q11: 779 | S11: 609 | T11: 851 | U11: 888 | V11: 983 | W11: 1050 | Z11: 936 | AA11: 839 | AB11: 917 | AC11: 836 | AD11: 950 | AG11: 879 | AH11: =SUM(D11:AG11) -> 17358 | AI11: =COUNT(D11:AG11) -> 20
A12: 5 | B12: Mr. DIPAK DATTATRAY KUMBHAR | C12: 102052667942 | E12: 940 | G12: 925 | H12: 987 | I12: 836 | J12: 954 | K12: 550 | L12: 833 | M12: 1140 | N12: 923 | O12: 903 | P12: 919 | Q12: 779 | S12: 609 | T12: 851 | U12: 756 | V12: 983 | Z12: 936 | AA12: 839 | AB12: 917 | AC12: 836 | AD12: 950 | AE12: 889 | AG12: 879 | AH12: =SUM(D12:AG12) -> 20134 | AI12: =COUNT(D12:AG12) -> 23
A13: 6 | B13: Mr. GIRISH SIDDHARAM MADYAL | C13: 101826609019 | E13: 940 | F13: 1130 | G13: 925 | H13: 987 | I13: 836 | J13: 954 | M13: 1140 | N13: 923 | O13: 903 | P13: 919 | Q13: 779 | S13: 609 | T13: 851 | U13: 888 | V13: 983 | W13: 1050 | X13: 1941 | Z13: 936 | AA13: 839 | AB13: 917 | AC13: 836 | AD13: 950 | AE13: 889 | AF13: 873 | AG13: 879 | AH13: =SUM(D13:AG13) -> 23877 | AI13: =COUNT(D13:AG13) -> 25
A14: 7 | B14: Mr.SHVSNAND LANDAGE | L14: 833 | AH14: =SUM(D14:AG14) -> 833 | AI14: =COUNT(D14:AG14) -> 1
A15: 8 | B15: Fulari | AE15: 550 | AH15: =SUM(D15:AG15) -> 550 | AI15: =COUNT(D15:AG15) -> 1
B16: Total | D16: =SUM(D8:D15) -> 550 | E16: =SUM(E8:E15) -> 4700 | F16: =SUM(F8:F15) -> 4696 | G16: =SUM(G8:G15) -> 5550 | H16: =SUM(H8:H15) -> 5922 | I16: =SUM(I8:I15) -> 4180 | J16: =SUM(J8:J15) -> 5724 | K16: =SUM(K8:K15) -> 1100 | ... AH16: =SUM(AH8:AH15) -> 126480 | AI16: =COUNT(D16:AG16) -> 30
B17: FINAL TEAM 2 | D17: =D16-D3 -> 550 | E17: =E16-E3 -> -4.92 | F17: =F16-F3 -> -500.62 | G17: =G16-G3 -> -5.22 | H17: =H16-H3 -> -5.68 | I17: =I16-I3 -> -0.22 | J17: =J16-J3 -> -1.28 | K17: =K16-K3 -> 1100 | ... AG17: =AG16-AG3 -> -4.46 | AH17: =SUM(D17:AG17) -> -2181.06 | AI17: =COUNT(D17:AG17) -> 30
B18: TOTAL AMOUNT | D18: =D20*D19 -> 0 | E18: =E20*E19 -> 4045.14 | F18: =F20*F19 -> 3550.8 | G18: =G20*G19 -> 5346.66 | H18: =H20*H19 -> 3077.14 | I18: =I20*I19 -> 6698.34 | J18: =J20*J19 -> 4063.62 | K18: =K20*K19 -> 0 | ... AG18: =AG20*AG19 -> 5463.04 | AH18: =SUM(D18:AG18) -> 120609.94 | AI18: =COUNT(D18:AG18) -> 30
B19: TOTAL MT | E19: 18.387 | F19: 16.14 | G19: 24.303 | H19: 13.987 | I19: 30.447 | J19: 18.471 | L19: 31.806 | M19: 23.796 | N19: 29.054 | O19: 20.71 | P19: 22.712 | Q19: 19.659 | S19: 22.044 | T19: 20.173 | U19: 24.774 | V19: 16.631 | X19: 30.148 | Z19: 20.175 | AA19: 23.181 | AB19: 22.116 | AC19: 17.191 | AD19: 20.657 | AE19: 22.811 | AF19: 14.022 | AG19: 24.832 | AH19: =SUM(D19:AG19) -> 548.227 | AI19: =COUNT(D19:AG19) -> 25
B20: Rate | D20: 220 | E20: 220 | F20: 220 | G20: 220 | H20: 220 | I20: 220 | J20: 220 | K20: 220 | L20: 220 | M20: 220 | N20: 220 | O20: 220 | P20: 220 | Q20: 220 | R20: 220 | S20: 220 | T20: 220 | U20: 220 | V20: 220 | W20: 220 | X20: 220 | Y20: 220 | Z20: 220 | AA20: 220 | AB20: 220 | AC20: 220 | AD20: 220 | AE20: 220 | AF20: 220 | AG20: 220 | AI20: =COUNT(D20:AG20) -> 30
B21: No.of Manpawar | E21: 5 | F21: 6 | G21: 6 | H21: 6 | I21: 5 | J21: 4 | L21: 6 | M21: 5 | N21: 6 | O21: 6 | P21: 6 | Q21: 6 | S21: 6 | T21: 6 | U21: 6 | V21: 5 | X21: 5 | Z21: 6 | AA21: 5 | AB21: 5 | AC21: 5 | AD21: 5 | AE21: 5 | AF21: 5 | AG21: 5 | AH21: =SUM(D21:AG21) -> 136 | AI21: =COUNT(D21:AG21) -> 25
B22: Paid Amount | D22: =D18/D21 -> #DIV/0! | E22: =E18/E21 -> 809.028 | F22: =F18/F21 -> 591.8 | G22: =G18/G21 -> 891.11 | H22: =H18/H21 -> 512.85667 | I22: =I18/I21 -> 1339.668 | J22: =J18/J21 -> 1015.905 | K22: =K18/K21 -> #DIV/0! | ... AG22: =AG18/AG21 -> 1092.608 | AH22: =SUM(D22:AG22) -> #DIV/0! | AI22: =COUNT(D22:AG22) -> 25
A23: 1 | B23: Ambare D.K | F23: 591 | G23: 891 | H23: 280 | L23: 982 | N23: 1065 | O23: 865 | P23: 686 | Q23: 610 | S23: 551 | T23: 740 | U23: 908 | V23: 732 | W23: 550 | X23: 1326 | Z23: 739 | AB23: 973 | AH23: =SUM(D23:AG23) -> 12489 | AI23: =COUNT(D23:AG23) -> 16
A24: 2 | B24: Mr. KASHINATH JAGANATH BIRJADAR | C24: 101818174092 | E24: 809 | F24: 591 | G24: 891 | H24: 559 | I24: 1339 | J24: 1015 | L24: 1202 | M24: 1047 | N24: 1065 | O24: 865 | P24: 862 | Q24: 742 | S24: 859 | T24: 740 | U24: 908 | W24: 550 | X24: 1326 | Z24: 739 | AA24: 1019 | AC24: 756 | AD24: 908 | AE24: 1003 | AF24: 616 | AG24: 1004 | AH24: =SUM(D24:AG24) -> 21415 | AI24: =COUNT(D24:AG24) -> 24
A25: 3 | B25: Mr. BHIMAHSNKAR SHARNAPPA ISHWARKATTI | C25: 102004077854 | E25: 809 | F25: 591 | G25: 891 | H25: 559 | I25: 1339 | J25: 1015 | L25: 1202 | M25: 1047 | N25: 1065 | O25: 865 | P25: 862 | Q25: 742 | S25: 859 | T25: 740 | U25: 908 | V25: 732 | W25: 550 | X25: 1326 | Z25: 739 | AA25: 1019 | AB25: 973 | AC25: 756 | AD25: 908 | AE25: 1003 | AF25: =616+873 -> 1489 | AG25: 1114 | AH25: =SUM(D25:AG25) -> 24103 | AI25: =COUNT(D25:AG25)+1 -> 27
A26: 4 | B26: Mr. SHIVANAND KANTAPPA KOSHTI | C26: 101817173110 | E26: 809 | F26: 591 | G26: 891 | H26: 559 | I26: 1339 | L26: 1202 | M26: 1047 | N26: 1065 | O26: 230 | P26: 862 | Q26: 742 | S26: 859 | T26: 740 | U26: 908 | V26: 732 | X26: 1326 | Z26: 739 | AA26: 1019 | AB26: 973 | AC26: 756 | AD26: 908 | AE26: 1003 | AF26: 616 | AG26: 1114 | AH26: =SUM(D26:AG26) -> 21030 | AI26: =COUNT(D26:AG26) -> 24
A27: 5 | B27: Mr. KHAJASAHEB GULAB HIMONE | C27: 102120964651 | E27: 809 | F27: 591 | G27: 891 | H27: 559 | I27: 1339 | J27: 1015 | L27: 1202 | M27: 1047 | N27: 1065 | O27: 865 | P27: 862 | Q27: 742 | S27: 859 | T27: 740 | U27: 908 | V27: 732 | W27: 550 | X27: 1326 | Z27: 739 | AA27: 1019 | AB27: 973 | AC27: 756 | AD27: 908 | AE27: 1003 | AF27: 616 | AG27: 1114 | AH27: =SUM(D27:AG27) -> 23230 | AI27: =COUNT(D27:AG27) -> 26
A28: 6 | B28: Mr. VISHAL SURESH MANE | C28: 101432431093 | E28: 809 | F28: 591 | G28: 891 | H28: 559 | I28: 1339 | J28: 1015 | L28: 1202 | M28: 1047 | N28: 1065 | O28: 865 | P28: 862 | Q28: 742 | S28: 859 | T28: 740 | U28: 908 | V28: 732 | Z28: 739 | AA28: 1019 | AB28: 973 | AC28: 756 | AD28: 908 | AE28: 1003 | AF28: 616 | AG28: 1114 | AH28: =SUM(D28:AG28) -> 21354 | AI28: =COUNT(D28:AG28) -> 24
B29: Total | D29: =SUM(D23:D28) -> 0 | E29: =SUM(E23:E28) -> 4045 | F29: =SUM(F23:F28) -> 3546 | G29: =SUM(G23:G28) -> 5346 | H29: =SUM(H23:H28) -> 3075 | I29: =SUM(I23:I28) -> 6695 | J29: =SUM(J23:J28) -> 4060 | K29: =SUM(K23:K28) -> 0 | ... AH29: =SUM(AH23:AH28) -> 123621 | AI29: =COUNT(D29:AG29) -> 30
B30: HAND EMARY 1 (GroupA) | D30: =D29-D18 -> 0 | E30: =E29-E18 -> -0.14 | F30: =F29-F18 -> -4.8 | G30: =G29-G18 -> -0.66 | H30: =H29-H18 -> -2.14 | I30: =I29-I18 -> -3.34 | J30: =J29-J18 -> -3.62 | K30: =K29-K18 -> 0 | ... AG30: =AG29-AG18 -> -3.04 | AH30: =SUM(D30:AG30) -> 3011.06 | AI30: =COUNT(D30:AG30) -> 30
B31: TOTAL AMOUNT | D31: =D32*D33 -> 0 | E31: =E32*E33 -> 6940.8 | F31: =F32*F33 -> 8104.96 | G31: =G32*G33 -> 7467.008 | H31: =H32*H33 -> 8408.32 | I31: =I32*I33 -> 6601.92 | J31: =J32*J33 -> 5987.2 | K31: =K32*K33 -> 0 | ... AG31: =AG32*AG33 -> 6517.76 | AH31: =SUM(D31:AG31) -> 168183.49 | AI31: =COUNT(D31:AG31) -> 30
B32: TOTAL MT | E32: 21.69 | F32: 25.328 | G32: 23.3344 | H32: 26.276 | I32: 20.631 | J32: 18.71 | L32: 20.54 | M32: 24.714 | N32: 17.58 | O32: 19.414 | P32: 14.583 | Q32: 14.877 | R32: 17.008 | S32: 13.17 | T32: 16.932 | U32: 19.653 | V32: 17.759 | W32: 21.011 | X32: 21.7 | Y32: 11.374 | Z32: 12.294 | AA32: 14.706 | AB32: 16.89 | AC32: 20.04 | AD32: 20.792 | AE32: 17.54 | AF32: 16.659 | AG32: 20.368 | AH32: =SUM(D32:AG32) -> 525.5734 | AI32: =COUNT(D32:AG32) -> 28
B33: Rate | D33: 320 | E33: 320 | F33: 320 | G33: 320 | H33: 320 | I33: 320 | J33: 320 | K33: 320 | L33: 320 | M33: 320 | N33: 320 | O33: 320 | P33: 320 | Q33: 320 | R33: 320 | S33: 320 | T33: 320 | U33: 320 | V33: 320 | W33: 320 | X33: 320 | Y33: 320 | Z33: 320 | AA33: 320 | AB33: 320 | AC33: 320 | AD33: 320 | AE33: 320 | AF33: 320 | AG33: 320 | AI33: =COUNT(D33:AG33) -> 30
B34: No.of Manpawar | E34: 7 | F34: 7 | G34: 7 | H34: 8 | I34: 7 | J34: 7 | L34: 7 | M34: 7 | N34: 6 | O34: 6 | P34: 7 | Q34: 7 | R34: 7 | S34: 5 | T34: 7 | U34: 7 | V34: 6 | W34: 8 | X34: 8 | Y34: 6 | Z34: 6 | AA34: 7 | AB34: 7 | AC34: 8 | AD34: 8 | AE34: 7 | AF34: 7 | AG34: 8 | AH34: =SUM(D34:AG34) -> 195 | AI34: =COUNT(D34:AG34) -> 28
B35: Paid Amount | D35: =D31/D34 -> #DIV/0! | E35: =E31/E34 -> 991.54286 | F35: =F31/F34 -> 1157.8514 | G35: =G31/G34 -> 1066.7154 | H35: =H31/H34 -> 1051.04 | I35: =I31/I34 -> 943.13143 | J35: =J31/J34 -> 855.31429 | K35: =K31/K34 -> #DIV/0! | ... AG35: =AG31/AG34 -> 814.72 | AH35: =SUM(D35:AG35) -> #DIV/0! | AI35: =COUNT(D35:AG35) -> 28
A36: 1 | B36: Mr. NAMDEV DURGAPPA BANDGAR | C36: 101407413648 | H36: 1131 | I36: 1008 | J36: 906 | L36: 1003 | M36: 1226 | N36: 1025 | O36: 1132 | P36: 686 | Q36: 701 | R36: 815 | T36: 811 | U36: 956 | V36: 1026 | W36: 900 | X36: 1065 | Y36: 617 | Z36: 708 | AA36: 721 | AB36: 809 | AC36: =772+837 -> 1609 | AD36: 783 | AG36: 902 | AH36: =SUM(D36:AG36) -> 20540 | AI36: =COUNT(D36:AG36)+1 -> 23
A37: 2 | B37: Mr. KHALID ILAI SHAIKH | C37: 101373078654 | E37: 1108 | F37: 1259 | G37: 1265 | H37: 1131 | I37: 1008 | J37: 906 | L37: 1003 | M37: 1226 | N37: 1025 | O37: 1132 | P37: 686 | Q37: 701 | S37: 1038 | T37: 811 | U37: 956 | W37: 900 | X37: 1065 | Z37: 708 | AA37: 721 | AB37: 809 | AC37: 837 | AD37: 713 | AE37: 806 | AF37: 857 | AG37: 902 | AH37: =SUM(D37:AG37) -> 23573 | AI37: =COUNT(D37:AG37) -> 25
A38: 3 | B38: Mr. WAGHMODE DATTATRAY ASHOK | C38: 101391642731 | E38: 1108 | F38: 1259 | G38: 1265 | H38: 1131 | I38: 1008 | J38: 906 | L38: 1003 | M38: 1226 | N38: 1025 | O38: 1132 | P38: 686 | Q38: 701 | T38: 811 | U38: 956 | V38: 1026 | W38: 900 | X38: 659 | Y38: 617 | AA38: 721 | AB38: 809 | AC38: 837 | AD38: 925 | AE38: 902 | AF38: 705 | AG38: 902 | AH38: =SUM(D38:AG38) -> 23220 | AI38: =COUNT(D38:AG38) -> 25
A39: 4 | B39: Mr. SATISH SHIVAJI SHINDE | C39: 101475170616 | E39: 1108 | F39: 1259 | G39: 1265 | H39: 1131 | I39: 1008 | J39: 906 | L39: 1003 | M39: 1226 | N39: 1025 | O39: 1132 | P39: 686 | Q39: 701 | S39: 1038 | T39: 811 | U39: 956 | V39: 1026 | W39: 900 | X39: 1065 | Z39: 708 | AA39: 553 | AB39: 809 | AC39: 837 | AD39: 925 | AE39: 902 | AF39: 705 | AG39: 902 | AH39: =SUM(D39:AG39) -> 24587 | AI39: =COUNT(D39:AG39) -> 26
A40: 5 | B40: Mr. KASHINATH ABHIMANU PATIL | C40: 101520450548 | E40: 1108 | F40: 1259 | G40: 1265 | H40: 1131 | I40: 1008 | J40: 906 | L40: 1003 | M40: 1226 | N40: 1025 | O40: 1132 | P40: 686 | Q40: 701 | R40: 815 | T40: 811 | U40: 956 | V40: 1026 | W40: 900 | X40: 1065 | Y40: 617 | Z40: 708 | AA40: 721 | AB40: 809 | AC40: 837 | AD40: 925 | AE40: 902 | AF40: 705 | AG40: 902 | AH40: =SUM(D40:AG40) -> 25149 | AI40: =COUNT(D40:AG40) -> 27
...

Sheet FINAL TANNAGE AMO.
B1: Day April-26 | D1: 1 | E1: 2 | F1: 3 | G1: 4 | H1: 5 | I1: 6 | J1: 7 | K1: 8 | L1: 9 | M1: 10 | N1: 11 | O1: 12 | P1: 13 | Q1: 14 | R1: 15 | S1: 16 | T1: 17 | U1: 18 | V1: 19 | W1: 20 | X1: 21 | Y1: 22 | Z1: 23 | AA1: 24 | AB1: 25 | AC1: 26 | AD1: 27 | AE1: 28 | AF1: 29 | AG1: 30 | AH1: Total
A2: 1 | B2: Mr. ANIL G MALI | C2: 101475240602 | E2: 940 | F2: 1130 | G2: 925 | H2: 987 | I2: 836 | J2: 954 | N2: 923 | P2: 919 | Q2: 779 | S2: 609 | T2: 851 | U2: 888 | V2: 983 | W2: 510 | X2: 1941 | AB2: 917 | AC2: 836 | AD2: 950 | AE2: 889 | AF2: 873 | AG2: 879 | AH2: =SUM(D2:AG2) -> 19519 | AI2: =COUNT(D2:AG2) -> 21 | AJ2: =VLOOKUP(C2,'Name Details'!A:C,3,0) -> Mr. ANIL G MALI | AK2: =AJ2=B2 -> TRUE
A3: 2 | B3: Mr. REVANASIDDH SHIVAPPA ISHWARKATTI | C3: 101492178974 | D3: 550 | E3: 940 | F3: 1130 | G3: 925 | H3: 987 | I3: 836 | J3: 954 | K3: 550 | L3: 833 | M3: 1140 | N3: 923 | O3: 903 | P3: 919 | Q3: 779 | R3: 550 | S3: 609 | T3: 851 | U3: 888 | V3: 983 | W3: 1050 | X3: 1941 | Y3: 550 | Z3: 936 | AF3: 873 | AG3: 879 | AH3: =SUM(D3:AG3) -> 22479 | AI3: =COUNT(D3:AG3) -> 25 | AJ3: =VLOOKUP(C3,'Name Details'!A:C,3,0) -> Mr. REVANASIDDH SHIVAPPA ISHWARKATTI | AK3: =AJ3=B3 -> TRUE
A4: 3 | B4: Mr. JITENDRA SIDRAM KOLI | C4: 101603294918 | E4: 940 | F4: 1130 | G4: 925 | H4: 987 | I4: 836 | J4: 954 | L4: 833 | M4: 1140 | N4: 923 | O4: 903 | P4: 919 | S4: 609 | T4: 851 | U4: 888 | V4: 983 | W4: 1050 | X4: 690 | Z4: 936 | AA4: 839 | AB4: 917 | AC4: 836 | AE4: 889 | AF4: 873 | AG4: 879 | AH4: =SUM(D4:AG4) -> 21730 | AI4: =COUNT(D4:AG4) -> 24 | AJ4: =VLOOKUP(C4,'Name Details'!A:C,3,0) -> Mr. JITENDRA SIDRAM KOLI | AK4: =AJ4=B4 -> TRUE
A5: 4 | B5: Mr. VIJAY BHARLE | C5: 101944505682 | F5: 176 | G5: 925 | H5: 987 | J5: 954 | L5: 833 | M5: 1140 | N5: 923 | O5: 903 | Q5: 779 | S5: 609 | T5: 851 | U5: 888 | V5: 983 | W5: 1050 | Z5: 936 | AA5: 839 | AB5: 917 | AC5: 836 | AD5: 950 | AG5: 879 | AH5: =SUM(D5:AG5) -> 17358 | AI5: =COUNT(D5:AG5) -> 20 | AJ5: =VLOOKUP(C5,'Name Details'!A:C,3,0) -> Mr. VIJAY BHARLE | AK5: =AJ5=B5 -> TRUE
A6: 5 | B6: Mr. DIPAK DATTATRAY KUMBHAR | C6: 102052667942 | E6: 940 | G6: 925 | H6: 987 | I6: 836 | J6: 954 | K6: 550 | L6: 833 | M6: 1140 | N6: 923 | O6: 903 | P6: 919 | Q6: 779 | S6: 609 | T6: 851 | U6: 756 | V6: 983 | Z6: 936 | AA6: 839 | AB6: 917 | AC6: 836 | AD6: 950 | AE6: 889 | AG6: 879 | AH6: =SUM(D6:AG6) -> 20134 | AI6: =COUNT(D6:AG6) -> 23 | AJ6: =VLOOKUP(C6,'Name Details'!A:C,3,0) -> Mr. DIPAK DATTATRAY KUMBHAR | AK6: =AJ6=B6 -> TRUE
A7: 6 | B7: Mr. GIRISH SIDDHARAM MADYAL | C7: 101826609019 | E7: 940 | F7: 1130 | G7: 925 | H7: 987 | I7: 836 | J7: 954 | M7: 1140 | N7: 923 | O7: 903 | P7: 919 | Q7: 779 | S7: 609 | T7: 851 | U7: 888 | V7: 983 | W7: 1050 | X7: 1941 | Z7: 936 | AA7: 839 | AB7: 917 | AC7: 836 | AD7: 950 | AE7: 889 | AF7: 873 | AG7: 879 | AH7: =SUM(D7:AG7) -> 23877 | AI7: =COUNT(D7:AG7) -> 25 | AJ7: =VLOOKUP(C7,'Name Details'!A:C,3,0) -> Mr. GIRISH SIDDHARAM MADYAL | AK7: =AJ7=B7 -> TRUE
A8: 7 | B8: Mr. SHAVRSIDDHA KHANDAPPA LANDAGE | C8: 101951607397 | L8: 833 | AH8: =SUM(D8:AG8) -> 833 | AI8: =COUNT(D8:AG8) -> 1 | AJ8: =VLOOKUP(C8,'Name Details'!A:C,3,0) -> Mr. SHAVRSIDDHA KHANDAPPA LANDAGE | AK8: =AJ8=B8 -> TRUE
A9: 8 | B9: Mr. SUFIYAN SHEKULAL FULARI | C9: 102125816854 | AE9: 550 | AH9: =SUM(D9:AG9) -> 550 | AI9: =COUNT(D9:AG9) -> 1 | AJ9: =VLOOKUP(C9,'Name Details'!A:C,3,0) -> Mr. SUFIYAN SHEKULAL FULARI | AK9: =AJ9=B9 -> TRUE
A10: 1 | B10: DHANNAJAY AMBURE | C10: DHANNAJAY AMBURE | F10: 591 | G10: 891 | H10: 280 | L10: 982 | N10: 1065 | O10: 865 | P10: 686 | Q10: 610 | S10: 551 | T10: 740 | U10: 908 | V10: 732 | W10: 550 | X10: 1326 | Z10: 739 | AB10: 973 | AH10: =SUM(D10:AG10) -> 12489 | AI10: =COUNT(D10:AG10) -> 16 | AJ10: =VLOOKUP(C10,'Name Details'!A:C,3,0) -> #N/A | AK10: =AJ10=B10 -> #N/A
A11: 2 | B11: Mr. KASHINATH JAGANATH BIRJADAR | C11: 101818174092 | E11: 809 | F11: 591 | G11: 891 | H11: 559 | I11: 1339 | J11: 1015 | L11: 1202 | M11: 1047 | N11: 1065 | O11: 865 | P11: 862 | Q11: 742 | S11: 859 | T11: 740 | U11: 908 | W11: 550 | X11: 1326 | Z11: 739 | AA11: 1019 | AC11: 756 | AD11: 908 | AE11: 1003 | AF11: 616 | AG11: 1004 | AH11: =SUM(D11:AG11) -> 21415 | AI11: =COUNT(D11:AG11) -> 24 | AJ11: =VLOOKUP(C11,'Name Details'!A:C,3,0) -> Mr. KASHINATH JAGANATH BIRJADAR | AK11: =AJ11=B11 -> TRUE
A12: 3 | B12: Mr. BHIMAHSNKAR SHARNAPPA ISHWARKATTI | C12: 102004077854 | E12: 809 | F12: 591 | G12: 891 | H12: 559 | I12: 1339 | J12: 1015 | L12: 1202 | M12: 1047 | N12: 1065 | O12: 865 | P12: 862 | Q12: 742 | S12: 859 | T12: 740 | U12: 908 | V12: 732 | W12: 550 | X12: 1326 | Z12: 739 | AA12: 1019 | AB12: 973 | AC12: 756 | AD12: 908 | AE12: 1003 | AF12: =616+873 -> 1489 | AG12: 1114 | AH12: =SUM(D12:AG12) -> 24103 | AI12: =COUNT(D12:AG12)+1 -> 27 | AJ12: =VLOOKUP(C12,'Name Details'!A:C,3,0) -> Mr. BHIMAHSNKAR SHARNAPPA ISHWARKATTI | AK12: =AJ12=B12 -> TRUE
A13: 4 | B13: Mr. SHIVANAND KANTAPPA KOSHTI | C13: 101817173110 | E13: 809 | F13: 591 | G13: 891 | H13: 559 | I13: 1339 | L13: 1202 | M13: 1047 | N13: 1065 | O13: 230 | P13: 862 | Q13: 742 | S13: 859 | T13: 740 | U13: 908 | V13: 732 | X13: 1326 | Z13: 739 | AA13: 1019 | AB13: 973 | AC13: 756 | AD13: 908 | AE13: 1003 | AF13: 616 | AG13: 1114 | AH13: =SUM(D13:AG13) -> 21030 | AI13: =COUNT(D13:AG13) -> 24 | AJ13: =VLOOKUP(C13,'Name Details'!A:C,3,0) -> Mr. SHIVANAND KANTAPPA KOSHTI | AK13: =AJ13=B13 -> TRUE
A14: 5 | B14: Mr. KHAJASAHEB GULAB HIMONE | C14: 102120964651 | E14: 809 | F14: 591 | G14: 891 | H14: 559 | I14: 1339 | J14: 1015 | L14: 1202 | M14: 1047 | N14: 1065 | O14: 865 | P14: 862 | Q14: 742 | S14: 859 | T14: 740 | U14: 908 | V14: 732 | W14: 550 | X14: 1326 | Z14: 739 | AA14: 1019 | AB14: 973 | AC14: 756 | AD14: 908 | AE14: 1003 | AF14: 616 | AG14: 1114 | AH14: =SUM(D14:AG14) -> 23230 | AI14: =COUNT(D14:AG14) -> 26 | AJ14: =VLOOKUP(C14,'Name Details'!A:C,3,0) -> Mr. KHAJASAHEB GULAB HIMONE | AK14: =AJ14=B14 -> TRUE
A15: 6 | B15: Mr. VISHAL SURESH MANE | C15: 101432431093 | E15: 809 | F15: 591 | G15: 891 | H15: 559 | I15: 1339 | J15: 1015 | L15: 1202 | M15: 1047 | N15: 1065 | O15: 865 | P15: 862 | Q15: 742 | S15: 859 | T15: 740 | U15: 908 | V15: 732 | Z15: 739 | AA15: 1019 | AB15: 973 | AC15: 756 | AD15: 908 | AE15: 1003 | AF15: 616 | AG15: 1114 | AH15: =SUM(D15:AG15) -> 21354 | AI15: =COUNT(D15:AG15) -> 24 | AJ15: =VLOOKUP(C15,'Name Details'!A:C,3,0) -> Mr. VISHAL SURESH MANE | AK15: =AJ15=B15 -> TRUE
A16: 1 | B16: Mr. NAMDEV DURGAPPA BANDGAR | C16: 101407413648 | H16: 1131 | I16: 1008 | J16: 906 | L16: 1003 | M16: 1226 | N16: 1025 | O16: 1132 | P16: 686 | Q16: 701 | R16: 815 | T16: 811 | U16: 956 | V16: 1026 | W16: 900 | X16: 1065 | Y16: 617 | Z16: 708 | AA16: 721 | AB16: 809 | AC16: =772+837 -> 1609 | AD16: 783 | AG16: 902 | AH16: =SUM(D16:AG16) -> 20540 | AI16: =COUNT(D16:AG16)+1 -> 23 | AJ16: =VLOOKUP(C16,'Name Details'!A:C,3,0) -> Mr. NAMDEV DURGAPPA BANDGAR | AK16: =AJ16=B16 -> TRUE
A17: 2 | B17: Mr. KHALID ILAI SHAIKH | C17: 101373078654 | E17: 1108 | F17: 1259 | G17: 1265 | H17: 1131 | I17: 1008 | J17: 906 | L17: 1003 | M17: 1226 | N17: 1025 | O17: 1132 | P17: 686 | Q17: 701 | S17: 1038 | T17: 811 | U17: 956 | W17: 900 | X17: 1065 | Z17: 708 | AA17: 721 | AB17: 809 | AC17: 837 | AD17: 713 | AE17: 806 | AF17: 857 | AG17: 902 | AH17: =SUM(D17:AG17) -> 23573 | AI17: =COUNT(D17:AG17) -> 25 | AJ17: =VLOOKUP(C17,'Name Details'!A:C,3,0) -> Mr. KHALID ILAI SHAIKH | AK17: =AJ17=B17 -> TRUE
A18: 3 | B18: Mr. WAGHMODE DATTATRAY ASHOK | C18: 101391642731 | E18: 1108 | F18: 1259 | G18: 1265 | H18: 1131 | I18: 1008 | J18: 906 | L18: 1003 | M18: 1226 | N18: 1025 | O18: 1132 | P18: 686 | Q18: 701 | T18: 811 | U18: 956 | V18: 1026 | W18: 900 | X18: 659 | Y18: 617 | AA18: 721 | AB18: 809 | AC18: 837 | AD18: 925 | AE18: 902 | AF18: 705 | AG18: 902 | AH18: =SUM(D18:AG18) -> 23220 | AI18: =COUNT(D18:AG18) -> 25 | AJ18: =VLOOKUP(C18,'Name Details'!A:C,3,0) -> Mr. WAGHMODE DATTATRAY ASHOK | AK18: =AJ18=B18 -> TRUE
A19: 4 | B19: Mr. SATISH SHIVAJI SHINDE | C19: 101475170616 | E19: 1108 | F19: 1259 | G19: 1265 | H19: 1131 | I19: 1008 | J19: 906 | L19: 1003 | M19: 1226 | N19: 1025 | O19: 1132 | P19: 686 | Q19: 701 | S19: 1038 | T19: 811 | U19: 956 | V19: 1026 | W19: 900 | X19: 1065 | Z19: 708 | AA19: 553 | AB19: 809 | AC19: 837 | AD19: 925 | AE19: 902 | AF19: 705 | AG19: 902 | AH19: =SUM(D19:AG19) -> 24587 | AI19: =COUNT(D19:AG19) -> 26 | AJ19: =VLOOKUP(C19,'Name Details'!A:C,3,0) -> Mr. SATISH SHIVAJI SHINDE | AK19: =AJ19=B19 -> TRUE
A20: 5 | B20: Mr. KASHINATH ABHIMANYU PATIL | C20: 101520450548 | E20: 1108 | F20: 1259 | G20: 1265 | H20: 1131 | I20: 1008 | J20: 906 | L20: 1003 | M20: 1226 | N20: 1025 | O20: 1132 | P20: 686 | Q20: 701 | R20: 815 | T20: 811 | U20: 956 | V20: 1026 | W20: 900 | X20: 1065 | Y20: 617 | Z20: 708 | AA20: 721 | AB20: 809 | AC20: 837 | AD20: 925 | AE20: 902 | AF20: 705 | AG20: 902 | AH20: =SUM(D20:AG20) -> 25149 | AI20: =COUNT(D20:AG20) -> 27 | AJ20: =VLOOKUP(C20,'Name Details'!A:C,3,0) -> Mr. KASHINATH ABHIMANYU PATIL | AK20: =AJ20=B20 -> TRUE
A21: 6 | B21: Mr. SAGAR RAMESH GHARSANGI | C21: 101154454730 | E21: 850 | F21: 1259 | G21: 592 | H21: 1131 | W21: 770 | AB21: 809 | AC21: 837 | AD21: 925 | AE21: 902 | AF21: 705 | AG21: 902 | AH21: =SUM(D21:AG21) -> 9682 | AI21: =COUNT(D21:AG21) -> 11 | AJ21: =VLOOKUP(C21,'Name Details'!A:C,3,0) -> Mr. SAGAR RAMESH GHARSANGI | AK21: =AJ21=B21 -> TRUE
A22: 7 | B22: AJAY SHRINIVAS PENTA | C22: AJAY SHRINIVAS PENTA | E22: 550 | F22: 550 | H22: 550 | I22: 550 | J22: 550 | Q22: 550 | S22: 550 | T22: 550 | U22: 550 | V22: 550 | W22: 550 | X22: 550 | Z22: 550 | AA22: 550 | AB22: 550 | AC22: 550 | AD22: 550 | AE22: 550 | AF22: 550 | AG22: 550 | AH22: =SUM(D22:AG22) -> 11000 | AI22: =COUNT(D22:AG22) -> 20 | AJ22: =VLOOKUP(C22,'Name Details'!A:C,3,0) -> #N/A | AK22: =AJ22=B22 -> #N/A
A23: 8 | B23: Mr. DHANRAJ DATTATRAY SHINDE | C23: 102260241245 | G23: 550 | AH23: =SUM(D23:AG23) -> 550 | AI23: =COUNT(D23:AG23) -> 1 | AJ23: =VLOOKUP(C23,'Name Details'!A:C,3,0) -> Mr. DHANRAJ DATTATRAY SHINDE | AK23: =AJ23=B23 -> TRUE
A24: 9 | B24: Mr. HARUN BASHA MULLA | C24: 102209140373 | L24: 550 | M24: 550 | O24: 550 | P24: 550 | R24: 550 | S24: 550 | X24: 550 | Y24: 550 | Z24: 550 | AA24: 550 | AD24: 550 | AE24: 550 | AF24: 550 | AG24: 550 | AH24: =SUM(D24:AG24) -> 7700 | AI24: =COUNT(D24:AG24) -> 14 | AJ24: =VLOOKUP(C24,'Name Details'!A:C,3,0) -> Mr. HARUN BASHA MULLA | AK24: =AJ24=B24 -> TRUE
A25: 10 | B25: ARJUN HIRACHAND BANDAGAR | C25: ARJUN HIRACHAND BANDAGAR | N25: 500 | AH25: =SUM(D25:AG25) -> 500 | AI25: =COUNT(D25:AG25) -> 1 | AJ25: =VLOOKUP(C25,'Name Details'!A:C,3,0) -> #N/A | AK25: =AJ25=B25 -> #N/A
A26: 12 | B26: Mr. ABHIJIT PIRAPPA WAGHMARE | C26: 101447270865 | R26: 815 | AF26: 705 | AH26: =SUM(D26:AG26) -> 1520 | AI26: =COUNT(D26:AG26) -> 2 | AJ26: =VLOOKUP(C26,'Name Details'!A:C,3,0) -> Mr. ABHIJIT PIRAPPA WAGHMARE | AK26: =AJ26=B26 -> TRUE
A27: 13 | B27: Mr. AKASH JAGNNATH TENGALE | C27: 101747190938 | E27: 1108 | F27: 565 | G27: 1265 | H27: 1131 | I27: 1008 | J27: 906 | L27: 1003 | M27: 1226 | AC27: 837 | AD27: 925 | AE27: 902 | AF27: 705 | AH27: =SUM(D27:AG27) -> 11581 | AI27: =COUNT(D27:AG27) -> 12 | AJ27: =VLOOKUP(C27,'Name Details'!A:C,3,0) -> Mr. AKASH JAGNNATH TENGALE | AK27: =AJ27=B27 -> TRUE
A28: 1 | B28: Mr. AMOL TEJU RATHOD | C28: 101509952020 | E28: 750 | F28: 956 | G28: 873 | H28: 856 | I28: 1030 | L28: 830 | M28: 946 | N28: 921 | O28: 909 | P28: 858 | Q28: 834 | S28: 900 | T28: 677 | U28: 1019 | V28: 800 | W28: 1003 | Z28: 659 | AA28: 842 | AB28: 731 | AC28: 772 | AE28: 957 | AF28: 857 | AG28: 953 | AH28: =SUM(D28:AG28) -> 19933 | AI28: =COUNT(D28:AG28) -> 23 | AJ28: =VLOOKUP(C28,'Name Details'!A:C,3,0) -> Mr. AMOL TEJU RATHOD | AK28: =AJ28=B28 -> TRUE
A29: 2 | B29: Mr. ANKUASH SANJAY BHALE | C29: 101835374035 | E29: 750 | F29: 956 | G29: 873 | H29: 343 | I29: 1030 | L29: 830 | M29: 946 | N29: 921 | O29: 418 | Q29: 701 | T29: 582 | AC29: 772 | AD29: 925 | AE29: 957 | AF29: 857 | AG29: 953 | AH29: =SUM(D29:AG29) -> 12814 | AI29: =COUNT(D29:AG29) -> 16 | AJ29: =VLOOKUP(C29,'Name Details'!A:C,3,0) -> Mr. ANKUASH SANJAY BHALE | AK29: =AJ29=B29 -> TRUE
A30: 3 | B30: Mr. MALLINATH SHIVARAM VHANAKADE | C30: 101522138160 | I30: 1030 | J30: 951 | L30: 830 | M30: 946 | N30: 921 | O30: 909 | P30: 858 | Q30: 834 | S30: 900 | T30: 677 | U30: 1019 | V30: 800 | W30: 1003 | X30: 803 | Z30: 659 | AA30: 842 | AF30: 857 | AG30: 953 | AH30: =SUM(D30:AG30) -> 15792 | AI30: =COUNT(D30:AG30) -> 18 | AJ30: =VLOOKUP(C30,'Name Details'!A:C,3,0) -> Mr. MALLINATH SHIVARAM VHANAKADE | AK30: =AJ30=B30 -> TRUE
A31: 4 | B31: Mr. DINESH VASANT SALGAR | C31: 102053057886 | E31: 750 | F31: 956 | G31: 873 | H31: 856 | I31: 1030 | J31: 951 | L31: 830 | M31: 946 | N31: 921 | O31: 909 | P31: 714 | Q31: 834 | R31: 815 | S31: 900 | T31: 677 | U31: 1019 | V31: 800 | W31: 1003 | X31: 803 | Y31: 617 | Z31: 659 | AA31: 721 | AB31: 731 | AC31: 772 | AD31: 901 | AE31: 957 | AG31: 953 | AH31: =SUM(D31:AG31) -> 22898 | AI31: =COUNT(D31:AG31) -> 27 | AJ31: =VLOOKUP(C31,'Name Details'!A:C,3,0) -> Mr. DINESH VASANT SALGAR | AK31: =AJ31=B31 -> TRUE
A32: 5 | B32: Mr. ROHAN BABURAV PANDIT | C32: 101424676055 | F32: 956 | G32: 873 | H32: 856 | I32: 1030 | J32: 951 | L32: 550 | N32: 921 | O32: 909 | P32: 858 | Q32: 834 | R32: 815 | S32: 900 | T32: 677 | U32: 1019 | V32: 800 | W32: 1003 | X32: 803 | AA32: 413 | AB32: 731 | AC32: 772 | AG32: 732 | AH32: =SUM(D32:AG32) -> 17403 | AI32: =COUNT(D32:AG32) -> 21 | AJ32: =VLOOKUP(C32,'Name Details'!A:C,3,0) -> Mr. ROHAN BABURAV PANDIT | AK32: =AJ32=B32 -> TRUE
A33: 6 | B33: Mr. YUVRAJ MALAKARI HIRKURE | C33: 102190249257 | J33: 951 | S33: 900 | U33: 1019 | V33: 800 | W33: 1003 | X33: 803 | Z33: 659 | AA33: 652 | AB33: 731 | AC33: 772 | AD33: 901 | AE33: 957 | AF33: 857 | AG33: 953 | AH33: =SUM(D33:AG33) -> 11958 | AI33: =COUNT(D33:AG33) -> 14 | AJ33: =VLOOKUP(C33,'Name Details'!A:C,3,0) -> Mr. YUVRAJ MALAKARI HIRKURE | AK33: =AJ33=B33 -> TRUE
A34: 7 | B34: Mr. ABHISHEK SUNIL RATHOD | C34: 102078951370 | F34: 956 | G34: 873 | H34: 856 | I34: 1030 | N34: 921 | O34: 909 | P34: 858 | Q34: 834 | V34: 800 | W34: 1003 | Z34: 659 | AA34: 842 | AB34: 731 | AD34: 494 | AH34: =SUM(D34:AG34) -> 11766 | AI34: =COUNT(D34:AG34) -> 14 | AJ34: =VLOOKUP(C34,'Name Details'!A:C,3,0) -> Mr. ABHISHEK SUNIL RATHOD | AK34: =AJ34=B34 -> TRUE
A35: 8 | B35: Mr. RAJAKUMAR BADIGER | C35: 102143026061 | M35: 946 | O35: 909 | Q35: 834 | S35: 900 | T35: 677 | U35: 1019 | V35: 800 | W35: 1003 | X35: 803 | Z35: 480 | AA35: 426 | AB35: 583 | AD35: 901 | AF35: 857 | AG35: 953 | AH35: =SUM(D35:AG35) -> 12091 | AI35: =COUNT(D35:AG35) -> 15 | AJ35: =VLOOKUP(C35,'Name Details'!A:C,3,0) -> Mr. RAJAKUMAR BADIGER | AK35: =AJ35=B35 -> TRUE
A36: 9 | B36: Mr. RAJSHEKHAR ANDODGI | C36: 101591620448 | E36: 750 | F36: 1259 | G36: 873 | I36: 1030 | J36: 951 | L36: 830 | M36: 946 | N36: 921 | O36: 990 | P36: 858 | Q36: 834 | T36: 677 | X36: 803 | Z36: 659 | AA36: 842 | AB36: 731 | AC36: 772 | AD36: 901 | AE36: 957 | AF36: 857 | AG36: 953 | AH36: =SUM(D36:AG36) -> 18394 | AI36: =COUNT(D36:AG36) -> 21 | AJ36: =VLOOKUP(C36,'Name Details'!A:C,3,0) -> Mr. RAJSHEKHAR ANDODGI | AK36: =AJ36=B36 -> TRUE
A37: 10 | B37: Mr. ANIL KUMAR RAWAT | C37: 101241926666 | F37: 956 | G37: 873 | H37: 856 | L37: 830 | M37: 946 | N37: 921 | P37: 858 | Q37: 834 | R37: 815 | T37: 677 | U37: 1019 | V37: 800 | W37: 1003 | X37: =406+803 -> 1209 | Y37: 617 | AA37: 842 | AB37: 731 | AC37: 650 | AD37: 901 | AE37: 806 | AH37: =SUM(D37:AG37) -> 17144 | AI37: =COUNT(D37:AG37)+1 -> 21 | AJ37: =VLOOKUP(C37,'Name Details'!A:C,3,0) -> Mr. ANIL KUMAR RAWAT | AK37: =AJ37=B37 -> TRUE
A38: 11 | B38: Mr. MANGESH NAVNATH ANKUSHRAO | C38: 101084612898 | F38: 956 | G38: 873 | H38: 811 | I38: 1030 | J38: 951 | S38: 1038 | T38: 811 | U38: 956 | V38: 1026 | W38: 900 | X38: 1065 | AH38: =SUM(D38:AG38) -> 10417 | AI38: =COUNT(D38:AG38) -> 11 | AJ38: =VLOOKUP(C38,'Name Details'!A:C,3,0) -> Mr. MANGESH NAVNATH ANKUSHRAO | AK38: =AJ38=B38 -> TRUE
A39: 12 | B39: Mr. PUNDALIK CHANDU JADHAV | C39: 101486099649 | E39: 750 | J39: 951 | M39: 1140 | P39: 686 | AA39: 839 | AD39: 950 | AH39: =SUM(D39:AG39) -> 5316 | AI39: =COUNT(D39:AG39) -> 6 | AJ39: =VLOOKUP(C39,'Name Details'!A:C,3,0) -> Mr. PUNDALIK CHANDU JADHAV | AK39: =AJ39=B39 -> TRUE
D40: =SUM(D2:D39) -> 550 | E40: =SUM(E2:E39) -> 19435 | F40: =SUM(F2:F39) -> 23603 | G40: =SUM(G2:G39) -> 25347 | H40: =SUM(H2:H39) -> 22898 | I40: =SUM(I2:I39) -> 25713 | J40: =SUM(J2:J39) -> 22427 | K40: =SUM(K2:K39) -> 1100 | ... AI40: =SUM(AI2:AI39) -> 675

Sheet REWORK
A1: 46113 | H1: FIRE WALL STATION REWORK TEAM
B3: 1) GHANTE SACHIN BHAGWAN | H3: 2) SAGAR BASVRAJ ARJUN | N3: 3) MUSTAK RASHID SHAIKH | T3: 4) CHOUGULE HRUSHIKESH CHANDRAKANT
B4: DATE | C4: QTY | D4: RATE | E4: AMOUNT | F4: PRESENTY | H4: DATE | I4: QTY | J4: RATE | K4: AMOUNT | L4: PRESENTY | N4: DATE | O4: QTY | P4: RATE | Q4: AMOUNT | R4: PRESENTY | T4: DATE | U4: QTY | V4: RATE | W4: AMOUNT | X4: PRESENTY
B5: 46113 | D5: 2.45 | E5: =C5*D5 -> 0 | F5: 550 | H5: 46113 | I5: 0 | J5: 2.45 | K5: =I5*J5 -> 0 | N5: 46113 | P5: 2.45 | Q5: =O5*P5 -> 0 | T5: 46113 | U5: 0 | V5: 2.45 | W5: =U5*V5 -> 0
B6: 46114 | D6: 2.45 | E6: =C6*D6 -> 0 | F6: 550 | H6: 46114 | I6: 0 | J6: 2.45 | K6: =I6*J6 -> 0 | N6: 46114 | P6: 2.45 | Q6: =O6*P6 -> 0 | T6: 46114 | U6: 0 | V6: 2.45 | W6: =U6*V6 -> 0
B7: 46115 | D7: 2.45 | E7: =C7*D7 -> 0 | F7: 550 | H7: 46115 | I7: 0 | J7: 2.45 | K7: =I7*J7 -> 0 | N7: 46115 | P7: 2.45 | Q7: =O7*P7 -> 0 | T7: 46115 | V7: 2.45 | W7: =U7*V7 -> 0 | X7: 550
B8: 46116 | D8: 2.45 | E8: =C8*D8 -> 0 | F8: 550 | H8: 46116 | I8: 0 | J8: 2.45 | K8: =I8*J8 -> 0 | N8: 46116 | P8: 2.45 | Q8: =O8*P8 -> 0 | T8: 46116 | V8: 2.45 | W8: =U8*V8 -> 0 | X8: 550
B9: 46117 | D9: 2.45 | E9: =C9*D9 -> 0 | F9: 550 | H9: 46117 | I9: 0 | J9: 2.45 | K9: =I9*J9 -> 0 | N9: 46117 | P9: 2.45 | Q9: =O9*P9 -> 0 | T9: 46117 | U9: 310 | V9: 2.45 | W9: =U9*V9 -> 759.5
B10: 46118 | D10: 2.45 | E10: =C10*D10 -> 0 | F10: 550 | H10: 46118 | I10: 0 | J10: 2.45 | K10: =I10*J10 -> 0 | N10: 46118 | P10: 2.45 | Q10: =O10*P10 -> 0 | T10: 46118 | U10: 286 | V10: 2.45 | W10: =U10*V10 -> 700.7
B11: 46119 | D11: 2.45 | E11: =C11*D11 -> 0 | F11: 550 | H11: 46119 | I11: 0 | J11: 2.45 | K11: =I11*J11 -> 0 | N11: 46119 | P11: 2.45 | Q11: =O11*P11 -> 0 | T11: 46119 | U11: 286 | V11: 2.45 | W11: =U11*V11 -> 700.7
B12: 46120 | C12: 0 | D12: 2.45 | E12: =C12*D12 -> 0 | H12: 46120 | I12: 0 | J12: 2.45 | K12: =I12*J12 -> 0 | N12: 46120 | P12: 2.45 | Q12: =O12*P12 -> 0 | T12: 46120 | V12: 2.45 | W12: =U12*V12 -> 0 | X12: 550
B13: 46121 | C13: 299 | D13: 2.45 | E13: =C13*D13 -> 732.55 | H13: 46121 | I13: 0 | J13: 2.45 | K13: =I13*J13 -> 0 | N13: 46121 | P13: 2.45 | Q13: =O13*P13 -> 0 | T13: 46121 | V13: 2.45 | W13: =U13*V13 -> 0 | X13: 550
B14: 46122 | C14: 280 | D14: 2.45 | E14: =C14*D14 -> 686 | H14: 46122 | I14: 0 | J14: 2.45 | K14: =I14*J14 -> 0 | N14: 46122 | P14: 2.45 | Q14: =O14*P14 -> 0 | T14: 46122 | V14: 2.45 | W14: =U14*V14 -> 0 | X14: 550
B15: 46123 | C15: 295 | D15: 2.45 | E15: =C15*D15 -> 722.75 | H15: 46123 | I15: 0 | J15: 2.45 | K15: =I15*J15 -> 0 | N15: 46123 | P15: 2.45 | Q15: =O15*P15 -> 0 | T15: 46123 | U15: 0 | V15: 2.45 | W15: =U15*V15 -> 0
B16: 46124 | C16: 316 | D16: 2.45 | E16: =C16*D16 -> 774.2 | F16: 550 | H16: 46124 | I16: 0 | J16: 2.45 | K16: =I16*J16 -> 0 | N16: 46124 | P16: 2.45 | Q16: =O16*P16 -> 0 | T16: 46124 | U16: 274 | V16: 2.45 | W16: =U16*V16 -> 671.3
B17: 46125 | C17: 286 | D17: 2.45 | E17: =C17*D17 -> 700.7 | H17: 46125 | I17: 0 | J17: 2.45 | K17: =I17*J17 -> 0 | N17: 46125 | P17: 2.45 | Q17: =O17*P17 -> 0 | T17: 46125 | U17: 0 | V17: 2.45 | W17: =U17*V17 -> 0
B18: 46126 | C18: 275 | D18: 2.45 | E18: =C18*D18 -> 673.75 | H18: 46126 | I18: 0 | J18: 2.45 | K18: =I18*J18 -> 0 | N18: 46126 | P18: 2.45 | Q18: =O18*P18 -> 0 | T18: 46126 | U18: 0 | V18: 2.45 | W18: =U18*V18 -> 0
B19: 46127 | C19: 0 | D19: 2.45 | E19: =C19*D19 -> 0 | H19: 46127 | I19: 0 | J19: 2.45 | K19: =I19*J19 -> 0 | N19: 46127 | P19: 2.45 | Q19: =O19*P19 -> 0 | T19: 46127 | V19: 2.45 | W19: =U19*V19 -> 0 | X19: 550
B20: 46128 | C20: 289 | D20: 2.45 | E20: =C20*D20 -> 708.05 | H20: 46128 | I20: 0 | J20: 2.45 | K20: =I20*J20 -> 0 | N20: 46128 | P20: 2.45 | Q20: =O20*P20 -> 0 | T20: 46128 | U20: 0 | V20: 2.45 | W20: =U20*V20 -> 0
B21: 46129 | C21: 305 | D21: 2.45 | E21: =C21*D21 -> 747.25 | H21: 46129 | I21: 0 | J21: 2.45 | K21: =I21*J21 -> 0 | N21: 46129 | P21: 2.45 | Q21: =O21*P21 -> 0 | T21: 46129 | U21: 273 | V21: 2.45 | W21: =U21*V21 -> 668.85
B22: 46130 | C22: 297 | D22: 2.45 | E22: =C22*D22 -> 727.65 | H22: 46130 | I22: 0 | J22: 2.45 | K22: =I22*J22 -> 0 | N22: 46130 | P22: 2.45 | Q22: =O22*P22 -> 0 | T22: 46130 | U22: 297 | V22: 2.45 | W22: =U22*V22 -> 727.65
B23: 46131 | C23: 277 | D23: 2.45 | E23: =C23*D23 -> 678.65 | H23: 46131 | I23: 0 | J23: 2.45 | K23: =I23*J23 -> 0 | N23: 46131 | P23: 2.45 | Q23: =O23*P23 -> 0 | T23: 46131 | V23: 2.45 | W23: =U23*V23 -> 0 | X23: 550
B24: 46132 | C24: 301 | D24: 2.45 | E24: =C24*D24 -> 737.45 | H24: 46132 | I24: 0 | J24: 2.45 | K24: =I24*J24 -> 0 | N24: 46132 | P24: 2.45 | Q24: =O24*P24 -> 0 | T24: 46132 | V24: 2.45 | W24: =U24*V24 -> 0 | X24: 550
B25: 46133 | C25: 279 | D25: 2.45 | E25: =C25*D25 -> 683.55 | H25: 46133 | I25: 0 | J25: 2.45 | K25: =I25*J25 -> 0 | N25: 46133 | P25: 2.45 | Q25: =O25*P25 -> 0 | T25: 46133 | U25: 264 | V25: 2.45 | W25: =U25*V25 -> 646.8
B26: 46134 | C26: 0 | D26: 2.45 | E26: =C26*D26 -> 0 | H26: 46134 | I26: 0 | J26: 2.45 | K26: =I26*J26 -> 0 | N26: 46134 | P26: 2.45 | Q26: =O26*P26 -> 0 | T26: 46134 | V26: 2.45 | W26: =U26*V26 -> 0 | X26: 550
B27: 46135 | D27: 2.45 | E27: =C27*D27 -> 0 | F27: 550 | H27: 46135 | I27: 0 | J27: 2.45 | K27: =I27*J27 -> 0 | N27: 46135 | P27: 2.45 | Q27: =O27*P27 -> 0 | T27: 46135 | V27: 2.45 | W27: =U27*V27 -> 0 | X27: 550
B28: 46136 | D28: 2.45 | E28: =C28*D28 -> 0 | F28: 550 | H28: 46136 | I28: 0 | J28: 2.45 | K28: =I28*J28 -> 0 | N28: 46136 | P28: 2.45 | Q28: =O28*P28 -> 0 | T28: 46136 | U28: 312 | V28: 2.45 | W28: =U28*V28 -> 764.4
B29: 46137 | D29: 2.45 | E29: =C29*D29 -> 0 | F29: 550 | H29: 46137 | I29: 0 | J29: 2.45 | K29: =I29*J29 -> 0 | N29: 46137 | P29: 2.45 | Q29: =O29*P29 -> 0 | T29: 46137 | U29: 242 | V29: 2.45 | W29: =U29*V29 -> 592.9
B30: 46138 | D30: 2.45 | E30: =C30*D30 -> 0 | F30: 550 | H30: 46138 | I30: 0 | J30: 2.45 | K30: =I30*J30 -> 0 | N30: 46138 | P30: 2.45 | Q30: =O30*P30 -> 0 | T30: 46138 | V30: 2.45 | W30: =U30*V30 -> 0 | X30: 550
B31: 46139 | D31: 2.45 | E31: =C31*D31 -> 0 | F31: 550 | H31: 46139 | I31: 0 | J31: 2.45 | K31: =I31*J31 -> 0 | N31: 46139 | P31: 2.45 | Q31: =O31*P31 -> 0 | T31: 46139 | V31: 2.45 | W31: =U31*V31 -> 0 | X31: 550
B32: 46140 | D32: 2.45 | E32: =C32*D32 -> 0 | F32: 550 | H32: 46140 | I32: 0 | J32: 2.45 | K32: =I32*J32 -> 0 | N32: 46140 | P32: 2.45 | Q32: =O32*P32 -> 0 | T32: 46140 | V32: 2.45 | W32: =U32*V32 -> 0
B33: 46141 | D33: 2.45 | E33: =C33*D33 -> 0 | F33: 550 | H33: 46141 | I33: 0 | J33: 2.45 | K33: =I33*J33 -> 0 | N33: 46141 | P33: 2.45 | Q33: =O33*P33 -> 0 | T33: 46141 | V33: 2.45 | W33: =U33*V33 -> 0 | X33: 550
B34: 46142 | D34: 2.45 | E34: =C34*D34 -> 0 | F34: 550 | H34: 46142 | I34: 0 | J34: 2.45 | K34: =I34*J34 -> 0 | N34: 46142 | P34: 2.45 | Q34: =O34*P34 -> 0 | T34: 46142 | U34: 221 | V34: 2.45 | W34: =U34*V34 -> 541.45
D35: 2.45 | E35: =C35*D35 -> 0 | J35: 2.45 | K35: =I35*J35 -> 0 | P35: 2.45 | Q35: =O35*P35 -> 0 | T35: 46112 | V35: 2.45 | W35: =U35*V35 -> 0
B36: TOTAL | C36: =SUM(C5:C35) -> 3499 | E36: =SUM(E5:E35) -> 8572.55 | F36: =SUM(F5:F35) -> 8800 | H36: TOTAL | I36: =SUM(I5:I35) -> 0 | K36: =SUM(K5:K35) -> 0 | L36: =SUM(L5:L35) -> 0 | N36: TOTAL | O36: =SUM(O5:O35) -> 0 | Q36: =SUM(Q5:Q35) -> 0 | R36: =SUM(R5:R35) -> 0 | T36: TOTAL | U36: =SUM(U5:U35) -> 2765 | W36: =SUM(W5:W35) -> 6774.25 | X36: =SUM(X5:X35) -> 7150
E37: =E36+F36 -> 17372.55 | K37: =K36+L36 -> 0 | R37: =Q36+R36 -> 0 | X37: =W36+X36 -> 13924.25
B38: 5) SOHEL SAHEBLAL JAMADAR | H38: 6)ARBAJ AMIN JAMADAR
B39: DATE | C39: QTY | D39: RATE | E39: AMOUNT | F39: PRESENTY | H39: DATE | I39: QTY | J39: RATE | K39: AMOUNT
B40: 46113 | C40: 0 | D40: 2.45 | E40: =C40*D40 -> 0 | H40: 46113 | I40: 0 | J40: 2.45 | K40: =I40*J40 -> 0
B41: 46114 | C41: 227 | D41: 2.45 | E41: =C41*D41 -> 556.15 | H41: 46114 | I41: 277 | J41: 2.45 | K41: =I41*J41 -> 678.65
...

Sheet Google attandance April -26
A1: 46113
A2: Sr No | B2: Panching No. | C2: UNA No. | D2: Emp Name | F2: 1 | G2: 2 | H2: 3 | I2: 4 | J2: 5 | K2: 6 | L2: 7 | M2: 8 | N2: 9 | O2: 10 | P2: 11 | Q2: 12 | R2: 13 | S2: 14 | T2: 15 | U2: 16 | V2: 17 | W2: 18 | X2: 19 | Y2: 20 | Z2: 21 | AA2: 22 | AB2: 23 | AC2: 24 | AD2: 25 | AE2: 26 | AF2: 27 | AG2: 28 | AH2: 29 | AI2: 30 | AJ2: Total
A3: 1 | B3: FOU29 | C3: 101540070377 | D3: SANTOSH LAXMAN KOLI | E3: AVG | T3: 1 | U3: 1 | V3: 1 | W3: 1 | X3: 1 | Y3: 1 | Z3: 1 | AA3: 1 | AB3: 1 | AC3: 1 | AD3: 2 | AE3: 2 | AF3: 1 | AG3: 1 | AH3: 1 | AI3: 1 | AJ3: =SUM(F3:AI3) -> 18 | AK3: =VLOOKUP(C3,'Name Details'!A:C,3,0) -> Mr. SANTOSH LAXMAN KOLI | AL3: =VLOOKUP(B3,'[2]APRIL-2026'!$B$1:$J$65536,9,0) -> #N/A | AN3: =VLOOKUP(C3,Work!D:F,3,0) -> Mr. SANTOSH LAXMAN KOLI | AO3: =AN3=AK3 -> TRUE | AP3: FOU29
A4: 2 | B4: FOU28 | C4: 101424675655 | D4: VIJAY VISHNU MANE | E4: AVG | F4: 1 | G4: 1 | H4: 1 | I4: 1 | J4: 1 | L4: 1 | N4: 1 | O4: 1 | P4: 1 | Q4: 1 | R4: 1 | S4: 1 | U4: 1 | V4: 1 | W4: 1 | X4: 1 | Y4: 1 | Z4: 1 | AB4: 1 | AC4: 1 | AD4: 1 | AE4: 1 | AF4: 1 | AG4: 1 | AH4: 1 | AI4: 1 | AJ4: =SUM(F4:AI4) -> 26 | AK4: =VLOOKUP(C4,'Name Details'!A:C,3,0) -> Mr. VIJAY MANE | AL4: =VLOOKUP(B4,'[2]APRIL-2026'!$B$1:$J$65536,9,0) -> 487.18 | AM4: 487.18 | AN4: =VLOOKUP(C4,Work!D:F,3,0) -> Mr. VIJAY MANE | AO4: =AN4=AK4 -> TRUE | AP4: FOU28
A5: 3 | B5: FOU277 | C5: 102090872186 | D5: MAHESH BABUSHA LANDAGE | E5: AVG | F5: 1 | G5: 1 | H5: 1 | I5: 1 | J5: 1 | N5: 1 | O5: 1 | P5: 1 | Q5: 1 | R5: 1 | S5: 1 | T5: 1 | U5: 1 | V5: 1 | W5: 1 | X5: 1 | Y5: 1 | Z5: 1 | AA5: 1 | AB5: 1 | AC5: 1 | AD5: 1 | AF5: 1 | AG5: 1 | AH5: 1 | AJ5: =SUM(F5:AI5) -> 25 | AK5: =VLOOKUP(C5,'Name Details'!A:C,3,0) -> Mr. MAHESH BABUSHA LANDAGE | AL5: =VLOOKUP(B5,'[2]APRIL-2026'!$B$1:$J$65536,9,0) -> 391.26 | AM5: 391.26 | AN5: =VLOOKUP(C5,Work!D:F,3,0) -> Mr. MAHESH BABUSHA LANDAGE | AO5: =AN5=AK5 -> TRUE | AP5: FOU277
A6: 4 | B6: FOU367 | C6: 101960331774 | D6: SAMARTH IRRANA DHAVANE | E6: AVG | F6: 1 | G6: 1 | H6: 1 | I6: 1 | J6: 1 | K6: 1 | L6: 1 | N6: 1 | O6: 1 | P6: 1 | Q6: 1 | R6: 1 | S6: 1 | T6: 1.5 | U6: 1 | V6: 1 | W6: 1 | X6: 1 | Y6: 1 | Z6: 1 | AB6: 1 | AC6: 1 | AG6: 1 | AH6: 1 | AI6: 1 | AJ6: =SUM(F6:AI6) -> 25.5 | AK6: =VLOOKUP(C6,'Name Details'!A:C,3,0) -> Mr. SAMARTH IRANNA DHAVANE | AL6: =VLOOKUP(B6,'[2]APRIL-2026'!$B$1:$J$65536,9,0) -> 154.24 | AM6: 154.24 | AN6: =VLOOKUP(C6,Work!D:F,3,0) -> Mr. SAMARTH IRANNA DHAVANE | AO6: =AN6=AK6 -> TRUE | AP6: FOU367
A7: 5 | B7: FOU703 | C7: 102267132379 | D7: VISHAL RAJKUMAR KOLI | E7: AVG | F7: 1 | H7: 1 | I7: 1 | J7: 1 | K7: 1 | L7: 1 | O7: 1 | P7: 1 | Q7: 1 | R7: 1 | S7: 1 | U7: 1 | V7: 1 | W7: 1 | X7: 1 | Y7: 1 | Z7: 1 | AB7: 1 | AC7: 1 | AD7: 1 | AE7: 1 | AF7: 1 | AG7: 1 | AI7: 0.5 | AJ7: =SUM(F7:AI7) -> 23.5 | AK7: =VLOOKUP(C7,'Name Details'!A:C,3,0) -> Mr. VISHAL RAJKUMAR KOLI | AL7: =VLOOKUP(B7,'[2]APRIL-2026'!$B$1:$J$65536,9,0) -> 448.66 | AM7: 448.66 | AN7: =VLOOKUP(C7,Work!D:F,3,0) -> Mr. VISHAL RAJKUMAR KOLI | AO7: =AN7=AK7 -> TRUE | AP7: FOU703
A8: 6 | B8: FOU79 | C8: 101281737627 | D8: AVINASH PATANGE | E8: AVG | J8: 1 | K8: 1 | L8: 1 | M8: 1 | N8: 1 | O8: 1 | P8: 1 | Q8: 1 | S8: 1 | X8: 1 | Y8: 1 | Z8: 1 | AB8: 1 | AD8: 1 | AE8: 1 | AF8: 1 | AJ8: =SUM(F8:AI8) -> 16 | AK8: =VLOOKUP(C8,'Name Details'!A:C,3,0) -> Mr. AVINASH NILKANTH PATANGE | AL8: =VLOOKUP(B8,'[2]APRIL-2026'!$B$1:$J$65536,9,0) -> 146.71 | AM8: 146.71 | AN8: =VLOOKUP(C8,Work!D:F,3,0) -> Mr. AVINASH NILKANTH PATANGE | AO8: =AN8=AK8 -> TRUE | AP8: FOU79
A9: 7 | B9: 0 | C9: SAMARTH MANJUNATH SIRSAT | D9: SAMARTH MANJUNATH SIRSAT | E9: AVG | G9: 1 | H9: 1 | I9: 1 | J9: 1 | K9: 1 | L9: 1 | O9: 1 | P9: 1 | Q9: 1 | T9: 1 | U9: 2 | V9: 1 | W9: 1 | Y9: 1 | Z9: 1 | AB9: 1 | AC9: 1 | AD9: 1 | AE9: 1 | AF9: 1 | AH9: 1 | AJ9: =SUM(F9:AI9) -> 22 | AK9: =VLOOKUP(C9,'Name Details'!A:C,3,0) -> #N/A | AL9: =VLOOKUP(B9,'[2]APRIL-2026'!$B$1:$J$65536,9,0) -> #N/A | AN9: =VLOOKUP(C9,Work!D:F,3,0) -> SAMARTH MANJUNATH SIRSAT | AO9: =AN9=AK9 -> #N/A | AP9: 0
A10: 8 | B10: FOU850 | C10: TURBE PARSHURAM MARUTI | D10: TURBE PARSHURAM MARUTI | E10: AVG | G10: 1 | H10: 1 | I10: 1 | J10: 1 | K10: 1 | L10: 1 | N10: 1 | O10: 1 | R10: 1 | S10: 1 | U10: 1 | AD10: 1 | AE10: 1 | AF10: 1 | AG10: 1 | AI10: 1 | AJ10: =SUM(F10:AI10) -> 16 | AK10: =VLOOKUP(C10,'Name Details'!A:C,3,0) -> #N/A | AL10: =VLOOKUP(B10,'[2]APRIL-2026'!$B$1:$J$65536,9,0) -> 337.15 | AM10: 337.15 | AN10: =VLOOKUP(C10,Work!D:F,3,0) -> TURBE PARSHURAM MARUTI | AO10: =AN10=AK10 -> #N/A | AP10: FOU850
A11: 9 | B11: FOU328 | C11: 101623086404 | D11: BANDENAVAJ MULLA | E11: AVG | H11: 1 | I11: 1 | J11: 1 | K11: 1 | L11: 1 | N11: 1 | P11: 1 | Q11: 1 | R11: 1 | S11: 1 | U11: 1 | V11: 1 | W11: 1 | X11: 1 | Y11: 1 | Z11: 1 | AB11: 1 | AC11: 1 | AD11: 1 | AE11: 1 | AF11: 1 | AG11: 1 | AH11: 1 | AI11: 1 | AJ11: =SUM(F11:AI11) -> 24 | AK11: =VLOOKUP(C11,'Name Details'!A:C,3,0) -> Mr. BANDENAWAJ SAIPAN MULLA | AL11: =VLOOKUP(B11,'[2]APRIL-2026'!$B$1:$J$65536,9,0) -> 433.21 | AM11: 433.21 | AN11: =VLOOKUP(C11,Work!D:F,3,0) -> Mr. BANDENAWAJ SAIPAN MULLA | AO11: =AN11=AK11 -> TRUE | AP11: FOU328
A12: 10 | B12: FOU84 | C12: 102028098436 | D12: BASAVARAJ TALWAR | E12: AVG | F12: 1 | G12: 1 | H12: 1 | I12: 1 | J12: 1 | K12: 1 | L12: 1 | M12: 1 | N12: 1 | O12: 1 | P12: 1 | Q12: 1 | R12: 1 | S12: 1 | T12: 1 | V12: 1 | W12: 1 | X12: 1 | Y12: 1 | Z12: 1 | AA12: 2 | AB12: 1 | AC12: 1 | AD12: 1 | AG12: 1 | AH12: 1 | AI12: 1 | AJ12: =SUM(F12:AI12) -> 28 | AK12: =VLOOKUP(C12,'Name Details'!A:C,3,0) -> Mr. BSAVRAJ IRANNA TALWAR | AL12: =VLOOKUP(B12,'[2]APRIL-2026'!$B$1:$J$65536,9,0) -> 413.8 | AM12: 413.8 | AN12: =VLOOKUP(C12,Work!D:F,3,0) -> Mr. BSAVRAJ IRANNA TALWAR | AO12: =AN12=AK12 -> TRUE | AP12: FOU84
A13: 11 | B13: FOU56 | C13: 101951607402 | D13: DAVALSAB NADAF MATTU | E13: AVG | F13: 1 | G13: 1 | H13: 1 | I13: 1 | J13: 1 | K13: 1 | L13: 1 | M13: 1 | N13: 1 | O13: 1 | P13: 1 | R13: 1 | S13: 1 | T13: 1 | U13: 1 | V13: 1 | W13: 1 | X13: 1 | Y13: 1 | Z13: 1 | AB13: 1 | AC13: 1 | AD13: 1 | AE13: 1 | AF13: 1 | AG13: 1 | AH13: 2 | AI13: 2 | AJ13: =SUM(F13:AI13) -> 30 | AK13: =VLOOKUP(C13,'Name Details'!A:C,3,0) -> Mr. DAVALSAB MATTU NADAF | AL13: =VLOOKUP(B13,'[2]APRIL-2026'!$B$1:$J$65536,9,0) -> 195.63 | AM13: 195.63 | AN13: =VLOOKUP(C13,Work!D:F,3,0) -> Mr. DAVALSAB MATTU NADAF | AO13: =AN13=AK13 -> TRUE | AP13: FOU56
A14: 12 | B14: FOU63 | C14: 101969547233 | D14: HEMANT ANAVIRAPPA NANDURE | E14: AVG | G14: 1 | H14: 1 | I14: 1 | N14: 1 | O14: 1 | P14: 1 | R14: 1 | S14: 1 | U14: 1 | V14: 1 | W14: 1 | X14: 0.5 | Y14: 1 | Z14: 1 | AB14: 1 | AC14: 1 | AD14: 1 | AE14: 1 | AF14: 1 | AG14: 1 | AH14: 1 | AI14: 1 | AJ14: =SUM(F14:AI14) -> 21.5 | AK14: =VLOOKUP(C14,'Name Details'!A:C,3,0) -> Mr. NANDURE HEMANT ANAVIRAPPA | AL14: =VLOOKUP(B14,'[2]APRIL-2026'!$B$1:$J$65536,9,0) -> 236.97 | AM14: 236.97 | AN14: =VLOOKUP(C14,Work!D:F,3,0) -> Mr. NANDURE HEMANT ANAVIRAPPA | AO14: =AN14=AK14 -> TRUE | AP14: FOU63
A15: 13 | B15: FOU90 | C15: 102043325356 | D15: AKIB SHAIKH | E15: AVG | F15: 1 | G15: 1 | I15: 1 | J15: 1 | K15: 1 | L15: 1 | M15: 1 | N15: 1 | O15: 1 | P15: 1 | R15: 1 | S15: 1 | T15: 1 | U15: 1 | V15: 1 | W15: 1 | X15: 1 | Y15: 1 | Z15: 1 | AB15: 1 | AC15: 1 | AD15: 1 | AE15: 1 | AF15: 1 | AG15: 1 | AH15: 1 | AI15: 1 | AJ15: =SUM(F15:AI15) -> 27 | AK15: =VLOOKUP(C15,'Name Details'!A:C,3,0) -> Mr. AKIB SHAIKH | AL15: =VLOOKUP(B15,'[2]APRIL-2026'!$B$1:$J$65536,9,0) -> 165.51 | AM15: 165.51 | AN15: =VLOOKUP(C15,Work!D:F,3,0) -> Mr. AKIB SHAIKH | AO15: =AN15=AK15 -> TRUE | AP15: FOU90
A16: 14 | B16: FOU625 | C16: 101958132802 | D16: IRANNA IDDHARAM KANNI | E16: AVG | G16: 1 | H16: 1 | I16: 1 | J16: 1 | K16: 1 | L16: 1 | N16: 1 | O16: 1 | P16: 1 | Q16: 1 | R16: 1 | S16: 1 | U16: 1 | V16: 1 | W16: 1 | Y16: 1 | Z16: 1 | AC16: 1 | AD16: 1 | AF16: 1 | AH16: 1 | AI16: 1 | AJ16: =SUM(F16:AI16) -> 22 | AK16: =VLOOKUP(C16,'Name Details'!A:C,3,0) -> Mr. IRANNA SIDDHARAM KANNI | AL16: =VLOOKUP(B16,'[2]APRIL-2026'!$B$1:$J$65536,9,0) -> 183.05 | AM16: 183.05 | AN16: =VLOOKUP(C16,Work!D:F,3,0) -> Mr. IRANNA SIDDHARAM KANNI | AO16: =AN16=AK16 -> TRUE | AP16: FOU625
A17: 15 | B17: FOU75 | C17: SAQIB SAYYAD | D17: SAQIB SAYYAD | E17: AVG | H17: 1 | I17: 1 | J17: 1 | K17: 1 | L17: 1 | M17: 1 | N17: 1 | O17: 1 | P17: 1 | Q17: 1 | R17: 1 | S17: 1 | T17: 1 | U17: 1 | V17: 1 | X17: 1 | Y17: 1 | AB17: 2 | AD17: 2 | AE17: 1 | AF17: 2 | AG17: 0.5 | AH17: 1 | AI17: 1 | AJ17: =SUM(F17:AI17) -> 26.5 | AK17: =VLOOKUP(C17,'Name Details'!A:C,3,0) -> #N/A | AL17: =VLOOKUP(B17,'[2]APRIL-2026'!$B$1:$J$65536,9,0) -> 423.25 | AM17: 423 | AN17: =VLOOKUP(C17,Work!D:F,3,0) -> SAQIB SAYYAD | AO17: =AN17=AK17 -> #N/A | AP17: FOU75
A18: 15 | B18: FOU624 | C18: 102232142117 | D18: AYAN ARIF USTAD | E18: AVG | AJ18: =SUM(F18:AI18) -> 0 | AK18: =VLOOKUP(C18,'Name Details'!A:C,3,0) -> Mr. AYAN ARIF USTAD | AL18: =VLOOKUP(B18,'[2]APRIL-2026'!$B$1:$J$65536,9,0) -> #N/A | AN18: =VLOOKUP(C18,Work!D:F,3,0) -> Mr. AYAN ARIF USTAD | AO18: =AN18=AK18 -> TRUE | AP18: FOU624
A19: 16 | B19: 0 | C19: 101216844424 | D19: HUSEN BABULAL NADAF | E19: AVG | G19: 1 | H19: 1 | I19: 1 | J19: 1 | K19: 1 | L19: 1 | Q19: 1 | R19: 1 | S19: 1 | U19: 1 | V19: 1 | W19: 1 | AB19: 1 | AC19: 1 | AD19: 1 | AJ19: =SUM(F19:AI19) -> 15 | AK19: =VLOOKUP(C19,'Name Details'!A:C,3,0) -> Mr. HUSEN NADAF | AL19: =VLOOKUP(B19,'[2]APRIL-2026'!$B$1:$J$65536,9,0) -> #N/A | AN19: =VLOOKUP(C19,Work!D:F,3,0) -> Mr. HUSEN NADAF | AO19: =AN19=AK19 -> TRUE | AP19: 0
